Workbook

Sheet Inhoudsopgave
A1: Inhoudsopgave | B1: Pagina
A4: T01 bestuur en ondersteuning | B4: 1
A5: T02 burgerzaken | B5: 8
A6: T03 beheer overige gebouwen en gronden | B6: 19
A7: T04 bedrijf | B7: 24
A8: T04 loon | B8: 34
A9: T04 werf | B9: 48
A10: T05 Treasury | B10: 54
A11: T06 1 OZB Woningen | B11: 56
A12: T06 2 OZB Niet-Woningen | B12: 60
A13: T06 4 Belastingen overig | B13: 63
A14: T07 Gemeentefonds en overige rijksuitkeringen | B14: 65
A15: T08 Overige baten en lasten | B15: 68
... A78: T83 wonen en bouwen | B78: 250

Sheet Inlees CODA
A1: Inleesbestand CODA
A2: Element 2 | B2: Element 3 | C2: Element 4 | D2: Element 5 | E2: 2025 | F2: 2026 | G2: 2027 | H2: 2028 | I2: 2029 | J2: Taakveld | K2: Toelichting
A3: 601001 | B3: 43819 | E3: 9573 | F3: 9822 | G3: 10038 | H3: 10259 | I3: 10485 | J3: T01
A4: 601001 | B4: 43812 | E4: 87915 | F4: 94864 | G4: 86556 | H4: 88285 | I4: 90051 | J4: T01
A5: 601001 | B5: 43812 | E5: 7716.168 | F5: 7916.7884 | G5: 8090.9577 | H5: 8268.9588 | I5: 8450.8759 | J5: T01
A6: 601001 | B6: 43812 | E6: 17077 | F6: 17522 | G6: 17907 | H6: 18302 | I6: 18705 | J6: T01
A7: 601001 | B7: 43812 | E7: 4085 | F7: 4191 | G7: 4283 | H7: 4377 | I7: 4473 | J7: T01
A8: 601002 | B8: 43819 | E8: 11538 | F8: 12121 | G8: 12387 | H8: 12660 | I8: 12938 | J8: T01
A9: 601002 | B9: 43812 | E9: 11401 | F9: 11801 | G9: 12149 | H9: 12504 | I9: 12867 | J9: T01
A10: 601003 | B10: 43812 | E10: 41778 | F10: 43712 | G10: 45231 | H10: 47118 | I10: 48879.5 | J10: T01
A11: 601004 | B11: 43812 | E11: 69833 | F11: 70000 | G11: 71540 | H11: 73114 | I11: 74723 | J11: T01
A12: 601005 | B12: 43812 | E12: 1684.892 | F12: 1728.6992 | G12: 1766.7306 | H12: 1805.5986 | I12: 1845.3218 | J12: T01
A13: 601901 | B13: 41000 | E13: 0 | F13: 0 | G13: 0 | H13: 0 | I13: 0 | J13: T01
A14: 601007 | B14: 41101 | E14: 88189 | F14: 117492 | G14: 119842 | H14: 50933 | I14: 0 | J14: T01
... A212: 604056 | B212: 43812 | E212: 1633 | F212: 1675 | G212: 1712 | H212: 1750 | I212: 1789 | J212: T04L
A213: #REF! | B213: 43812 | E213: 20000 | F213: 31806 | G213: 20971 | H213: 42894 | I213: 21904 | J213: T04L
A214: 604057 | B214: 43819 | E214: 78963 | F214: 103802 | G214: 106086 | H214: 108420 | I214: 110805 | J214: T04L
A215: 604057 | B215: 43812 | E215: 27992 | F215: 28719 | G215: 29351 | H215: 29998 | I215: 30659 | J215: T04L
A216: 604062 | B216: 43812 | E216: 154451 | F216: 158003 | G216: 96232 | H216: 98445 | I216: 100611 | J216: T04L
A217: 604043 | B217: 43511 | E217: 0 | F217: 0 | G217: 0 | H217: 0 | I217: 0 | J217: T04L
A218: 604901 | B218: 41100 | E218: 9206076.2 | F218: 9137962 | G218: 9562142 | H218: 9929614 | I218: 10395576 | J218: T04L
A219: 604901 | B219: 43511 | E219: 107000 | F219: 0 | G219: 0 | H219: 0 | I219: 0 | J219: T04L
A220: 604901 | B220: 47300 | E220: 0 | F220: 0 | G220: 0 | H220: 0 | I220: 0 | J220: T04L
A221: 604901 | B221: 47501 | E221: -341698.03 | F221: -352192.4 | G221: -359406.36 | H221: -377737.77 | I221: -396946.97 | J221: T04L
A222: 604901 | B222: 47501 | E222: -268835.37 | F222: -251701.74 | G222: -256858.3 | H222: -269956.82 | I222: -283685.95 | J222: T04L
A223: 604901 | B223: 47501 | E223: -198502 | F223: -186350 | G223: -190170 | H223: -199866 | I223: -210031 | J223: T04L
A224: 604901 | B224: 41100 | E224: 8931 | F224: 8918 | G224: 9328 | H224: 9757 | I224: 10206 | J224: T04L
A225: 604901 | B225: 41100 | E225: 10369.98 | F225: 12280.7 | G225: 12846 | H225: 13437 | I225: 14055 | J225: T04L
... A645: 629005 | B645: 44380 | E645: 133617 | F645: 0 | G645: 0 | H645: 0 | I645: 0 | J645: T51
A646: 629006 | B646: 44380 | F646: 461877 | G646: 466014 | H646: 470345 | I646: 474854 | J646: T51
A647: 629901 | B647: 41100 | E647: 118700.44 | F647: 140596.75 | G647: 147065 | H647: 153830 | I647: 160907 | J647: T51
A648: 629004 | B648: 84310 | E648: -19408 | F648: -14923 | G648: -14923 | H648: -14924 | I648: -14924 | J648: T51
A649: 629005 | B649: 84310 | E649: -133617 | F649: -129081 | G649: -129081 | H649: -129080 | I649: -129080 | J649: T51
A650: 630001 | B650: 42100 | E650: 7092 | F650: 7276 | G650: 7436 | H650: 7600 | I650: 7767 | J650: T52
A651: 630001 | B651: 43806 | E651: 1155 | F651: 1185 | G651: 1211 | H651: 1238 | I651: 1265 | J651: T52
A652: 630005 | B652: 42100 | E652: 1589 | F652: 1630 | G652: 1666 | H652: 1703 | I652: 1740 | J652: T52
A653: 630005 | B653: 43511 | E653: 1010.8 | F653: 1031.2 | G653: 1078.8 | H653: 1156.61 | I653: 1156.61 | J653: T52
A654: 630005 | B654: 43806 | E654: 517 | F654: 530 | G654: 542 | H654: 554 | I654: 566 | J654: T52
A655: 630005 | B655: 43812 | E655: 955 | F655: 980 | G655: 1002 | H655: 1024 | I655: 1047 | J655: T52
A656: 630002 | B656: 42100 | E656: 958 | F656: 983 | G656: 1005 | H656: 1027 | I656: 1050 | J656: T52
...

Sheet draaitabel inlees CODA
A2: Element 3 | B2: (Alle)
A4: Rijlabels | B4: Som van 2026 | C4: Som van 2027 | D4: Som van 2028 | E4: Som van 2029
A5: 601001 | B5: 134315.79 | C5: 126874.96 | D5: 129491.96 | E5: 132164.88
A6: 601002 | B6: 23922 | C6: 24536 | D6: 25164 | E6: 25805
A7: 601003 | B7: 43712 | C7: 45231 | D7: 47118 | E7: 48879.5
A8: 601004 | B8: 70000 | C8: 71540 | D8: 73114 | E8: 74723
A9: 601005 | B9: 1728.6992 | C9: 1766.7306 | D9: 1805.5986 | E9: 1845.3218
A10: 601007 | B10: 0 | C10: 0 | D10: 0 | E10: 0
A11: 601008 | B11: 18740 | C11: 19152 | D11: 19574 | E11: 20003
A12: 601010 | B12: 35717 | C12: 36502 | D12: 37304 | E12: 38124
A13: 601011 | B13: 24153 | C13: 24684 | D13: 25227 | E13: 25782
A14: 601012 | B14: 321495 | C14: 340729 | D14: 357023 | E14: 377551.05
A15: 601013 | B15: 79636 | C15: 84595 | D15: 87532.6 | E15: 93374.148
A16: 601014 | B16: 29867 | C16: 31241 | D16: 32678 | E16: 34181
... A189: 617021 | B189: 72819 | C189: 72819 | D189: 72819 | E189: 259615
A190: 617023 | B190: 500000
A191: 617901 | B191: 1579483.8 | C191: 1866724 | D191: 2186933 | E191: 2508648
A192: 617902 | B192: 0 | C192: 0 | D192: 0 | E192: 0
A193: 617903 | B193: 14736 | C193: 15414 | D193: 16123 | E193: 16865
A194: 618001 | B194: 45653.891 | C194: 46729.393 | D194: 47828.242 | E194: 68955.896
A195: 618901 | B195: 31806 | C195: 31806 | D195: 31806 | E195: 81806
A196: 621001 | B196: 95236.3 | C196: 97339.4 | D196: 99489.48 | E196: 101685.54
A197: 621002 | B197: 1417 | C197: 1445 | D197: 1476 | E197: 1506
A198: 621901 | B198: 7452.51 | C198: 7565 | D198: 7683 | E198: 7806
A199: 622001 | B199: 1469 | C199: 1502 | D199: 1535 | E199: 1569
A200: 622003 | B200: 27830 | C200: 28451 | D200: 29077 | E200: 29707
A201: 622004 | B201: 0 | C201: 0 | D201: 0 | E201: 0.056814965
A202: 622005 | B202: 232833 | C202: 225443 | D202: 230403 | E202: 235472
... A513: 696001 | B513: 85000 | C513: 89000 | D513: 93000 | E513: 97000
A514: 635016 | B514: 337000 | C514: 0 | D514: 0 | E514: 0
A515: 649024 | B515: 0 | C515: -1000000 | D515: -1000000 | E515: -1000000
A516: 651015 | B516: 50000 | C516: 50000 | D516: 0 | E516: 0
A517: Eindtotaal | B517: -1700582.9 | C517: -1455914.4 | D517: 1142980.5 | E517: 887102.62
A520: Eindtotaal draaitabel | B520: -1700582.9 | C520: -1455914.4 | D520: 1142980.5 | E520: 887102.62
B521: -980246.6 | C521: -946399.04 | D521: -3851192.2 | E521: -4003624.4 | F521: t/m 28-8-2025
A523: Verwacht begrotingssaldo - start van de begroting | B523: -1003000 | C523: -873000 | D523: -4317000 | E523: -4931000
A524: Begrotingssaldo 2026-2029 | B524: 364489.35 | C524: 344581.87 | D524: -3873182.7 | E524: -4232187.2
A526: Verschil | B526: =B524-B523 -> 1367489.4 | C526: =C524-C523 -> 1217581.9 | D526: =D524-D523 -> 443817.33 | E526: =E524-E523 -> 698812.78
A527: Correctie reserves | B527: =-B561 -> -1460000 | C527: =-C561 -> -1737500 | D527: =-D561 -> 0 | E527: =-E561 -> 0
A528: Correctie rente | B528: 0 | C528: 300000 | D528: -150000 | E528: 450000
...

Sheet draaitabel inlees CODA (2)
A2: Element 3 | B2: 41100
A4: Rijlabels | B4: Som van 2026
A5: 601901 | B5: 1503457.5
A6: T01 | B6: 1503457.5
A7: 601902 | B7: 172976.63
A8: T01 | B8: 172976.63
A9: 602901 | B9: 100258.11
A10: T02 | B10: 100258.11
A11: 602902 | B11: 118349.84
A12: T02 | B12: 118349.84
A13: 602903 | B13: 116735.24
A14: T02 | B14: 116735.24
A15: 602904 | B15: 119739.37
A16: T02 | B16: 119739.37
A17: 602905 | B17: 40461.45
A18: T02 | B18: 40461.45
A19: 602906 | B19: 169988.77
A20: T02 | B20: 169988.77
A21: 602907 | B21: 7848
A22: T02 | B22: 7848
A23: 603901 | B23: 158580.05
A24: T03 | B24: 158580.05
A25: 604002 | B25: 300000
A26: T04L | B26: 300000
A27: 604017 | B27: 31600
A28: T04B | B28: 31600
A29: 604901 | B29: 9058262
A30: T04L | B30: 9058262
A31: 605901 | B31: 0
A32: T05 | B32: 0
A33: 606901 | B33: 92269
A34: T061 | B34: 92269
A35: 607901 | B35: 77455
A36: T062 | B36: 77455
A37: 609901 | B37: 65986
A38: T064 | B38: 65986
A39: 611901 | B39: 0
A40: T08 | B40: 0
A41: 615901 | B41: 53449.78
A42: T11 | B42: 53449.78
...

Sheet afschrijvingen
A2: Rijlabels | B2: Som van 2026 | C2: Som van 2027 | D2: Som van 2028 | E2: Som van 2029
A3: 601901 | B3: 5000 | C3: 5000 | D3: 5000 | E3: 5000
A4: 603901 | B4: 39979 | C4: 28411 | D4: 28411 | E4: 28411
A5: 604045 | B5: 31559 | C5: 31559 | D5: 31559 | E5: 31559
A6: 604046 | B6: 0 | C6: 0 | D6: 0 | E6: 0
A7: 604048 | B7: 46895 | C7: 55121 | D7: 55121 | E7: 55121
A8: 604901 | B8: 443300 | C8: 684780 | D8: 657411 | E8: 628224
A9: 604902 | B9: -78454 | C9: -86680 | D9: -86680 | E9: -86680
A10: 605002 | B10: 0 | C10: 0 | D10: 0 | E10: 0
A11: 605901
A12: 615901 | B12: 11467 | C12: 29498 | D12: 29498 | E12: 29498
A13: 616903 | B13: 4519 | C13: 10000 | D13: 10000 | E13: 10000
A14: 617014 | B14: 0 | C14: 0 | D14: 0 | E14: 0
A15: 617016
A16: 617017 | B16: 0 | C16: 0 | D16: 0 | E16: 0
A17: 617018 | B17: 29812.42 | C17: 32938.42 | D17: 32938.42 | E17: 32938.42
A18: 617901 | B18: 813230 | C18: 1073107 | D18: 1364887 | E18: 1657064
A19: 617903 | B19: 0 | C19: 0 | D19: 0 | E19: 0
A20: 618901 | B20: 31806 | C20: 31806 | D20: 31806 | E20: 81806
A21: 621901 | B21: 5000 | C21: 5000 | D21: 5000 | E21: 5000
A22: 622901 | B22: 0 | C22: 0 | D22: 0 | E22: 0
A23: 627901 | B23: 1369938 | C23: 1366235 | D23: 2090360 | E23: 2203027
A24: 630022 | B24: 0 | C24: 0 | D24: 0 | E24: 0
A25: 630023 | B25: 22751.66 | C25: 25137.2 | D25: 25137.2 | E25: 25137.2
A26: 630901 | B26: 777187 | C26: 808687 | D26: 701859 | E26: 773169
A27: 634901 | B27: 98704 | C27: 98704 | D27: 98704 | E27: 98704
... A40: 688901 | B40: 235 | C40: 0 | D40: 0 | E40: 0
A41: Eindtotaal | B41: 4006425.9 | C41: 4936730 | D41: 5898764 | E41: 6428433
A43: Begroting 2025 | B43: 4202810 | C43: 4879877 | D43: 4972334
A45: verschil | B45: =GETPIVOTDATA("Som van 2026",'draaitabel inlees CODA'!$A$4)-B43 -> -5903392.9 | C45: =GETPIVOTDATA("Som van 2026",'draaitabel inlees CODA'!$A$4)-C43 -> -6580459.9 | D45: =GETPIVOTDATA("Som van 2026",'draaitabel inlees CODA'!$A$4)-D43 -> -6672916.9 | E45: =GETPIVOTDATA("Som van 2026",'draaitabel inlees CODA'!$A$4)-E43 -> -1700582.9
A47: nieuw beleid | B47: 0 | C47: =21334+13267+3533+28067+17600+5267+297334+16667+266667 -> 669736 | D47: =25000+21334+562400+13267+3533+5000+28067+17600+5267+297333+16667+16667+266667+83334 -> 1362136
A49: correctie in FF | B49: 235182 | C49: 714924 | D49: 384745
A51: restant | B51: =B43+B47-B41-B49 -> -38797.9 | C51: =C43+C47-C41-C49 -> -102041.02 | D51: =D43+D47-D41-D49 -> 50960.98 | E51: =E43+E47-E41-E49 -> -6428433
B54: =B41-B43 -> -196384.1

Sheet controle
A1: Rijlabels | B1: Som van 2026 | C1: Som van 2027 | D1: Som van 2028 | E1: Som van 2029 | F1: verschil 2028
A2: T01 | B2: 2947171.6 | C2: 2598568.7 | D2: 2709143.2 | E2: 2830665.9 | F2: =controle!D2-controle!C2 -> 110574.47
A3: T010 | B3: -4523443 | C3: -2757998 | D3: -2144788 | E3: -2265651 | F3: =controle!D3-controle!C3 -> 613210
A4: T011 | B4: 0 | C4: 0 | D4: 0 | E4: 0 | F4: =controle!D4-controle!C4 -> 0
A5: T02 | B5: 509576 | C5: 521878.63 | D5: 551790.56 | E5: 583844.87 | F5: =controle!D5-controle!C5 -> 29911.932
A6: T03 | B6: -41339.485 | C6: -50662.047 | D6: -48132.266 | E6: -45405.369 | F6: =controle!D6-controle!C6 -> 2529.7803
A7: T04B | B7: 2813365.7 | C7: 3097094.3 | D7: 3132756.8 | E7: 3169045.7 | F7: =controle!D7-controle!C7 -> 35662.43
A8: T04L | B8: 11319252 | C8: 11985724 | D8: 12471658 | E8: 13096449 | F8: =controle!D8-controle!C8 -> 485934.13
A9: T04W | B9: 2.0008883e-11 | C9: 0 | D9: -5.0931703e-11 | E9: 3.2741809e-11 | F9: =controle!D9-controle!C9 -> -5.0931703e-11
A10: T05 | B10: 81449.853 | C10: 220805.12 | D10: 372027.54 | E10: 367921.87 | F10: =controle!D10-controle!C10 -> 151222.43
A11: T061 | B11: -5487204.5 | C11: -6204408 | D11: -6795381 | E11: -7422117 | F11: =controle!D11-controle!C11 -> -590973
A12: T062 | B12: -3885527 | C12: -4383929 | D12: -4763146 | E12: -5175167 | F12: =controle!D12-controle!C12 -> -379217
A13: T064 | B13: -20300.492 | C13: -20383.379 | D13: -20439.337 | E13: -20340.279 | F13: =controle!D13-controle!C13 -> -55.958273
... A60: T83 | B60: 716424.48 | C60: 730021 | D60: 779681 | E60: 836333 | F60: =controle!D60-controle!C60 -> 49660
A61: Eindtotaal | B61: -1700582.9 | C61: -1455914.4 | D61: 1142980.5 | E61: 887102.62
A70: nieuw | B70: 2813365.7 | C70: 3097094.3 | D70: 3132756.8 | E70: 3169045.7
A71: oud | B71: 2966934 | C71: 2987781 | D71: 3038806
B72: =B70-B71 -> -153568.32 | C72: =C70-C71 -> 109313.34 | D72: =D70-D71 -> 93950.768 | E72: =E70-E71 -> 3169045.7

Sheet Details1
A1: Details voor Som van 2029 - Taakveld: T83
A3: Element 2 | B3: Element 3 | C3: Element 4 | D3: Element 5 | E3: 2025 | F3: 2026 | G3: 2027 | H3: 2028 | I3: 2029 | J3: Taakveld
A4: 653001 | B4: 43812 | E4: 22113 | F4: 22622 | G4: 23211 | H4: 23722 | I4: 24243 | J4: T83 | N4: 2025
A5: 653002 | B5: 43812 | E5: 50733 | F5: 52754 | G5: 53845 | H5: 56176 | I5: 58610 | J5: T83 | N5: =28300000 -> 28300000 | P5: =N5*2.2% -> 622600
A6: 653002 | B6: 43511 | E6: 31633 | F6: 32361 | G6: 33202 | H6: 33932 | I6: 34679 | J6: T83 | L6: 0.042 | M6: 2 | N6: -600000
A7: 653003 | B7: 43511 | E7: 144626 | F7: 147952 | G7: 151799 | H7: 155139 | I7: 158552 | J7: T83 | N7: 700000 | P7: KB 2026
A8: 653004 | B8: 43511 | E8: 39206 | F8: 40108 | G8: 41151 | H8: 42056 | I8: 42981 | J8: T83 | N8: -200000 | P8: Onderuitputting - besparing
A9: 653005 | B9: 83700 | E9: -1140000 | F9: -1140000 | G9: -1140000 | H9: -1140000 | I9: -1140000 | J9: T83 | N9: -100000 | P9: Verrekening opslag
A10: 653006 | B10: 83700 | E10: -11235 | F10: -11493 | G10: -11792 | H10: -12051 | I10: -12316 | J10: T83
A11: 653006 | B11: 43813 | E11: 17762 | F11: 18171 | G11: 18643 | H11: 19053 | I11: 19472 | J11: T83 | N11: -100000 | P11: PG
A12: 653007 | B12: 43812 | E12: 18947 | F12: 19383 | G12: 19887 | H12: 20325 | I12: 20772 | J12: T83 | N12: =SUM(N5:N11) -> 28000000
A13: 653008 | B13: 43812 | E13: 1184 | F13: 1211 | G13: 1242 | H13: 1269 | I13: 1297 | J13: T83
A14: 653009 | B14: 43511 | E14: 185914 | F14: 190190 | G14: 195135 | H14: 199428 | I14: 203815 | J14: T83
A15: 653010 | B15: 43511 | E15: 23683 | F15: 24228 | G15: 24858 | H15: 25405 | I15: 25964 | J15: T83
A16: 653011 | B16: 43511 | E16: 22237 | F16: 22748 | G16: 23339 | H16: 23852 | I16: 24377 | J16: T83
A17: 653012 | B17: 43812 | E17: 16340 | F17: 16716 | G17: 17151 | H17: 17528 | I17: 17914 | J17: T83
A18: 653013 | B18: 43812 | E18: 208023 | F18: 153831 | G18: 117319 | H18: 114899 | I18: 115514 | J18: T83
A19: 653014 | B19: 43511 | E19: 30700 | F19: 31400 | G19: 32200 | H19: 32200 | I19: 32200 | J19: T83
A20: 653901 | B20: 83800 | E20: -39323 | F20: -40227 | G20: -41273 | H20: -42181 | I20: -43109 | J20: T83
A21: 653901 | B21: 41100 | E21: 906685.85 | F21: 640300.9 | G21: 653107 | H21: 683150 | I21: 714575 | J21: T83
A22: 653902 | B22: 43812 | E22: 88426 | F22: 90515 | G22: 92867 | H22: 94887 | I22: 96944 | J22: T83
A23: 653902 | B23: 41100 | E23: 355295.08 | F23: 149055.58 | G23: 152037 | H23: 159031 | I23: 166346 | J23: T83

Sheet Inhoudsopgave 2
A1: Inhoudsopgave | B1: Pagina
A4: T01 bestuur en ondersteuning | B4: 1
A5: T02 burgerzaken | B5: 8
A6: T03 beheer overige gebouwen en gronden | B6: 19
A7: T04 bedrijf | B7: 24
A8: T04 loon | B8: 34
A9: T04 werf | B9: 48
A10: T05 Treasury | B10: 54
A11: T06 1 OZB Woningen | B11: 56
A12: T06 2 OZB Niet-Woningen | B12: 60
A13: T06 4 Belastingen overig | B13: 63
A14: T07 Gemeentefonds en overige rijksuitkeringen | B14: 65
A15: T08 Overige baten en lasten | B15: 68
... A76: T83 wonen en bouwen | B76: 261

Sheet Indexering
D1: 2021 | E1: 2022 | F1: 2023 | G1: 2024 | H1: 2025 | I1: 2026 | J1: 2027 | K1: 2028 | L1: 2029 | M1: 2030
J2: Hoofdjaar | K2: Hoofdjaar +1 | L2: Hoofdjaar +2 | M2: Hoofdjaar +3
B4: Prijsindex | D4: 1.015 | E4: 1.014 | F4: 1.024 | G4: 1.037 | H4: 1.028 | I4: 1.026 | J4: 1.021 | K4: 1.023 | L4: 1.023 | M4: 1.023
B5: Loonindex | D5: 1.031 | E5: 1.015 | F5: 1.046 | G5: 1.052 | H5: 1.049 | I5: 1.02 | J5: 1.042 | K5: 1.037 | L5: 1.037 | M5: 1.037
E6: =+(E4+E5)/2 -> 1.0145 | F6: =+(F4+F5)/2 -> 1.035 | G6: =+(G4+G5)/2 -> 1.0445 | H6: 1.036 | I6: =+I13 -> 1.02282 | J6: =+J13 -> 1.03213 | K6: =+K13 -> 1.03042 | L6: =+L13 -> 1.03042 | M6: =+M13 -> 1.03042
B7: Sociaal domein loonindex | J7: 1.042 | K7: 1.042 | L7: 1.042 | M7: 1.042
I8: =+H6-I6 -> 0.01318
F11: =+H4*0.47 -> 0.48316 | I11: =+I4*0.47 -> 0.48222 | J11: =+J4*0.47 -> 0.47987 | K11: =+K4*0.47 -> 0.48081 | L11: =+L4*0.47 -> 0.48081 | M11: =+M4*0.47 -> 0.48081
F12: =+H5*0.53 -> 0.55597 | I12: =+I5*0.53 -> 0.5406 | J12: =+J5*0.53 -> 0.55226 | K12: =+K5*0.53 -> 0.54961 | L12: =+L5*0.53 -> 0.54961 | M12: =+M5*0.53 -> 0.54961
F13: =+F11+F12 -> 1.03913 | I13: =+I11+I12 -> 1.02282 | J13: =+J11+J12 -> 1.03213 | K13: =+K11+K12 -> 1.03042 | L13: =+L11+L12 -> 1.03042 | M13: =+M11+M12 -> 1.03042
H16: Index conform kaderbrief
H18: 1.028 | I18: 1.023 | J18: 1.023 | K18: 1.023
H19: 1.049 | I19: 1.042 | J19: 1.042 | K19: 1.042
H20: 1.036 | I20: 1.0325 | J20: 1.0325 | K20: 1.0325

Sheet Verwerkingscontrole
F1: Primitieve begroting | L1: Gewijzigde begroting (recap) | P1: Mutaties | U1: Toelichting
A3: Taakveld | C3: Omschrijving | E3: 2025 | F3: 2026 | G3: 2027 | H3: 2028 | K3: 2025 | L3: 2026 | M3: 2027 | N3: 2028 | P3: 2025 | Q3: 2026 | R3: 2027 | S3: 2028 | V3: 2025 | W3: 2026 | X3: 2027 | Y3: 2028
A4: T01 bestuur en ondersteuning.xlsx | B4: T01 | C4: Bestuur | D4: L | E4: 2638500.7 | F4: 2646582.3 | G4: 2757419.5 | H4: 2865885.4 | J4: L | K4: =Recap!#REF! -> #REF! | L4: =Recap!E3 -> 4096256.6 | M4: =Recap!F3 -> 3519006 | N4: =Recap!G3 -> 3429319.8 | P4: =K4-E4 -> #REF! | Q4: =L4-F4 -> 1449674.3 | R4: =M4-G4 -> 761586.56 | S4: =N4-H4 -> 563434.38 | U4: W01-2025 | V4: 100000
U5: W02-2025 | V5: 10000 | W5: 10000 | X5: 10000 | Y5: 10000
U6: W02-2025 | V6: 4000 | W6: 14000 | X6: 4000 | Y6: 4000
A7: T02 burgerzaken.xlsx | B7: T02 | C7: Burgerzaken | D7: L | E7: 1150625.5 | F7: 1229061.5 | G7: 1290202.9 | H7: 1332894.2 | J7: L | K7: =Recap!#REF! -> #REF! | L7: =Recap!E4 -> 1279045.3 | M7: =Recap!F4 -> 1306068.9 | N7: =Recap!G4 -> 1349138.8 | P7: =K7-E7 -> #REF! | Q7: =L7-F7 -> 49983.764 | R7: =M7-G7 -> 15866.046 | S7: =N7-H7 -> 16244.526 | U7: W02-2025 | V7: 10400
A8: T03 beheer overige gebouwen en gronden.xlsx | B8: T03 | C8: Beheer overige gebouwen en gronden | D8: L | E8: 349018 | F8: 307885 | G8: 305512 | H8: 315036 | J8: L | K8: =Recap!#REF! -> #REF! | L8: =Recap!E5 -> 653245.52 | M8: =Recap!F5 -> 339365.95 | N8: =Recap!G5 -> 348755.73 | P8: =K8-E8 -> #REF! | Q8: =L8-F8 -> 345360.52 | R8: =M8-G8 -> 33853.953 | S8: =N8-H8 -> 33719.734
A9: T04 bedrijf.xlsx | B9: T04B | C9: Overhead - 1 bedrijfsvoering | D9: L | E9: 3036473.8 | F9: 2975494.8 | G9: 2996539.2 | H9: 3047765.1 | J9: L | K9: =Recap!#REF! -> #REF! | L9: =Recap!E6 -> 3325272.6 | M9: =Recap!F6 -> 3607658.3 | N9: =Recap!G6 -> 3180175.8 | P9: =K9-E9 -> #REF! | Q9: =L9-F9 -> 349777.72 | R9: =M9-G9 -> 611119.18 | S9: =N9-H9 -> 132410.73
A10: T04 loon.xlsx | B10: T04L | C10: Overhead - 2 loonkosten | D10: L | E10: 11485863 | F10: 11835935 | G10: 12250280 | H10: 12855626 | J10: L | K10: =Recap!#REF! -> #REF! | L10: =Recap!E7 -> 11367751 | M10: =Recap!F7 -> 11709325 | N10: =Recap!G7 -> 12465644 | P10: =K10-E10 -> #REF! | Q10: =L10-F10 -> -468184.28 | R10: =M10-G10 -> -540955.4 | S10: =N10-H10 -> -389981.58
A11: T04 werf.xlsx | B11: T04W | C11: Overhead - 3 werf en vervoermiddelen | D11: L | E11: 0 | F11: 0 | G11: 0 | H11: 0 | J11: L | K11: =Recap!#REF! -> #REF! | L11: =Recap!E8 -> 0 | M11: =Recap!F8 -> 0 | N11: =Recap!G8 -> 0 | P11: =K11-E11 -> #REF! | Q11: =L11-F11 -> 0 | R11: =M11-G11 -> 0 | S11: =N11-H11 -> 0
A12: T05 Treasury.xlsx | B12: T05 | C12: Treasury | D12: L | E12: 61245 | F12: 92483 | G12: 266627 | H12: 439206 | J12: L | K12: =Recap!#REF! -> #REF! | L12: =Recap!E9 -> 204771 | M12: =Recap!F9 -> 629078 | N12: =Recap!G9 -> 1083905 | P12: =K12-E12 -> #REF! | Q12: =L12-F12 -> 112288 | R12: =M12-G12 -> 362451 | S12: =N12-H12 -> 644699
A13: T06 1 OZB Woningen.xlsx | B13: T061 | C13: OZB Woningen | D13: L | E13: 179046 | F13: 185090 | G13: 191357 | H13: 197851 | J13: L | K13: =Recap!#REF! -> #REF! | L13: =Recap!E10 -> 172088 | M13: =Recap!F10 -> 177644 | N13: =Recap!G10 -> 183043 | P13: =K13-E13 -> #REF! | Q13: =L13-F13 -> -13002 | R13: =M13-G13 -> -13713 | S13: =N13-H13 -> -14808
A14: T06 2 OZB Niet-Woningen.xlsx | B14: T062 | C14: OZB Niet woningen | D14: L | E14: 138814 | F14: 143662 | G14: 148690 | H14: 153907 | J14: L | K14: =Recap!#REF! -> #REF! | L14: =Recap!E11 -> 130667 | M14: =Recap!F11 -> 135042 | N14: =Recap!G11 -> 139255 | P14: =K14-E14 -> #REF! | Q14: =L14-F14 -> -12995 | R14: =M14-G14 -> -13648 | S14: =N14-H14 -> -14652
A15: T06 4 Belastingen overig.xlsx | B15: T064 | C15: Belastingen overig | D15: L | E15: 63955 | F15: 66641 | G15: 69440 | H15: 72356 | J15: L | K15: =Recap!#REF! -> #REF! | L15: =Recap!E12 -> 65986 | M15: =Recap!F12 -> 68757 | N15: =Recap!G12 -> 71301 | P15: =K15-E15 -> #REF! | Q15: =L15-F15 -> -655 | R15: =M15-G15 -> -683 | S15: =N15-H15 -> -1055
A16: T07 Gemeentefonds en overige rijksuitkeringen.xlsx | B16: T07 | C16: Alg. uitkeringen en ov uitkeringen gemeentefonds | D16: L | E16: 5645 | F16: 5775 | G16: 5908 | H16: 6044 | J16: L | K16: =Recap!#REF! -> #REF! | L16: =Recap!E13 -> 5780 | M16: =Recap!F13 -> 5901 | N16: =Recap!G13 -> 6037 | P16: =K16-E16 -> #REF! | Q16: =L16-F16 -> 5 | R16: =M16-G16 -> -7 | S16: =N16-H16 -> -7
A17: T08 Overige baten en lasten.xlsx | B17: T08 | C17: Overige baten en lasten | D17: L | E17: 207972 | F17: 230693 | G17: 234994 | H17: 239394 | J17: L | K17: =Recap!#REF! -> #REF! | L17: =Recap!E14 -> 594431.35 | M17: =Recap!F14 -> 233854 | N17: =Recap!G14 -> 238228 | P17: =K17-E17 -> #REF! | Q17: =L17-F17 -> 363738.35 | R17: =M17-G17 -> -1140 | S17: =N17-H17 -> -1166 | U17: W01-2025 | V17: 120000 | W17: 123000 | X17: 127000 | Y17: 130000
A18: T09 Vennootschapsbelasting.xlsx | B18: T09 | C18: Vennootschapsbelasting | D18: L | E18: 0 | F18: 5000 | G18: 5000 | H18: 5000 | J18: L | K18: =Recap!#REF! -> #REF! | L18: =Recap!E15 -> 11400 | M18: =Recap!F15 -> 11400 | N18: =Recap!G15 -> 11400 | P18: =K18-E18 -> #REF! | Q18: =L18-F18 -> 6400 | R18: =M18-G18 -> 6400 | S18: =N18-H18 -> 6400
A19: T010 Mutaties Reserve.xlsx | B19: T010 | C19: Mutaties reserves | D19: L | E19: 423871 | F19: 336578 | G19: 336288 | H19: 335987 | J19: L | K19: =Recap!#REF! -> #REF! | L19: =Recap!E16 -> 905588 | M19: =Recap!F16 -> 471829 | N19: =Recap!G16 -> 438368 | P19: =K19-E19 -> #REF! | Q19: =L19-F19 -> 569010 | R19: =M19-G19 -> 135541 | S19: =N19-H19 -> 102381
A20: T011 Resultaat rekening baten en lasten.xlsx | B20: T011 | C20: Resultaat van de rekening van baten en lasten | D20: L | E20: 0 | F20: 0 | G20: 0 | H20: 2 | J20: L | K20: =Recap!#REF! -> #REF! | L20: =Recap!E17 -> 0 | M20: =Recap!F17 -> 0 | N20: =Recap!G17 -> 0 | P20: =K20-E20 -> #REF! | Q20: =L20-F20 -> 0 | R20: =M20-G20 -> 0 | S20: =N20-H20 -> -2
A21: T11 crisisbeheersing en brandweer.xlsx | B21: T11 | C21: Crisisbeheersing en brandweer | D21: L | E21: 1964601 | F21: 2046117 | G21: 2134352 | H21: 2222835 | J21: L | K21: =Recap!#REF! -> #REF! | L21: =Recap!E18 -> 2088526.5 | M21: =Recap!F18 -> 2264477.9 | N21: =Recap!G18 -> 2326060.9 | P21: =K21-E21 -> #REF! | Q21: =L21-F21 -> 42409.532 | R21: =M21-G21 -> 130125.94 | S21: =N21-H21 -> 103225.85
A22: T12 openbare orde en veiligheid.xlsx | B22: T12 | C22: Openbare orde en veiligheid | D22: L | E22: 1679340.3 | F22: 1746066.9 | G22: 1797877.9 | H22: 1868557.8 | J22: L | K22: =Recap!#REF! -> #REF! | L22: =Recap!E19 -> 2005361.2 | M22: =Recap!F19 -> 1932160.2 | N22: =Recap!G19 -> 1999201.4 | P22: =K22-E22 -> #REF! | Q22: =L22-F22 -> 259294.27 | R22: =M22-G22 -> 134282.37 | S22: =N22-H22 -> 130643.63
A23: T21 Verkeer en vervoer.xlsx | B23: T21 | C23: Verkeer en vervoer | D23: L | E23: 3624954.3 | F23: 3837871.7 | G23: 4166670.5 | H23: 4361801.4 | J23: L | K23: =Recap!#REF! -> #REF! | L23: =Recap!E20 -> 4152536.9 | M23: =Recap!F20 -> 4859110.9 | N23: =Recap!G20 -> 5275649.8 | P23: =K23-E23 -> #REF! | Q23: =L23-F23 -> 314665.18 | R23: =M23-G23 -> 692440.46 | S23: =N23-H23 -> 913848.35
A24: T22 parkeren.xlsx | B24: T22 | C24: Parkeren | D24: L | E24: 88269.931 | F24: 89637.833 | G24: 91040.353 | H24: 92477.233 | J24: L | K24: =Recap!#REF! -> #REF! | L24: =Recap!E21 -> 89294.891 | M24: =Recap!F21 -> 90577.142 | N24: =Recap!G21 -> 91996.267 | P24: =K24-E24 -> #REF! | Q24: =L24-F24 -> -342.94146 | R24: =M24-G24 -> -463.21053 | S24: =N24-H24 -> -480.96587
A25: T25 openbaar vervoer.xlsx | B25: T25 | C25: Openbaar vervoer | D25: L | E25: 78581.49 | F25: 80320 | G25: 82101 | H25: 83927 | J25: L | K25: =Recap!#REF! -> #REF! | L25: =Recap!E22 -> 99454.81 | M25: =Recap!F22 -> 101593.02 | N25: =Recap!G22 -> 103963.27 | P25: =K25-E25 -> #REF! | Q25: =L25-F25 -> 19134.81 | R25: =M25-G25 -> 19492.02 | S25: =N25-H25 -> 20036.27
A26: T31 economische ontwikkeling.xlsx | B26: T31 | C26: Economische ontwikkeling | D26: L | E26: 869239.44 | F26: 895173.69 | G26: 910956.14 | H26: 939885.72 | J26: L | K26: =Recap!#REF! -> #REF! | L26: =Recap!E23 -> 1355577.6 | M26: =Recap!F23 -> 1122696.5 | N26: =Recap!G23 -> 1152490.1 | P26: =K26-E26 -> #REF! | Q26: =L26-F26 -> 460403.87 | R26: =M26-G26 -> 211740.39 | S26: =N26-H26 -> 212604.39
A27: T33 bedrijfsloket en bedrijfsregelingen.xlsx | B27: T33 | C27: Bedrijvenloket en bedrijvenregeling | D27: L | E27: 37083.62 | F27: 38417.024 | G27: 39801.504 | H27: 41241.464 | J27: L | K27: =Recap!#REF! -> #REF! | L27: =Recap!E24 -> 41976.024 | M27: =Recap!F24 -> 43502.504 | N27: =Recap!G24 -> 44931.464 | P27: =K27-E27 -> #REF! | Q27: =L27-F27 -> 3559 | R27: =M27-G27 -> 3701 | S27: =N27-H27 -> 3690
A28: T34 economische promotie.xlsx | B28: T34 | C28: Economische promotie | D28: L | E28: 476690.77 | F28: 484795.75 | G28: 493218.76 | H28: 502008.59 | J28: L | K28: =Recap!#REF! -> #REF! | L28: =Recap!E25 -> 517402.83 | M28: =Recap!F25 -> 526952.76 | N28: =Recap!G25 -> 536047.59 | P28: =K28-E28 -> #REF! | Q28: =L28-F28 -> 32607.08 | R28: =M28-G28 -> 33734 | S28: =N28-H28 -> 34039
A29: T42 onderwijshuisvesting.xlsx | B29: T42 | C29: Onderwijshuisvesting | D29: L | E29: 958258.62 | F29: 1742768.6 | G29: 2235701.1 | H29: 2360346.3 | J29: L | K29: =Recap!#REF! -> #REF! | L29: =Recap!E26 -> 1735325.4 | M29: =Recap!F26 -> 1740867.3 | N29: =Recap!G26 -> 3159300.5 | P29: =K29-E29 -> #REF! | Q29: =L29-F29 -> -7443.1948 | R29: =M29-G29 -> -494833.83 | S29: =N29-H29 -> 798954.18
A30: T43 onderwijsbeleid en leerlingenzaken.xlsx | B30: T43 | C30: Onderwijsbeleid en leerlingenzaken | D30: L | E30: 1779281.4 | F30: 1823915 | G30: 1870313 | H30: 1919495 | J30: L | K30: =Recap!#REF! -> #REF! | L30: =Recap!E27 -> 1829738.2 | M30: =Recap!F27 -> 1882242 | N30: =Recap!G27 -> 1908620 | P30: =K30-E30 -> #REF! | Q30: =L30-F30 -> 5823.23 | R30: =M30-G30 -> 11929 | S30: =N30-H30 -> -10875 | U30: W01-2025 | V30: 8160 | W30: 8261 | X30: 8629 | Y30: 9021
A31: T51 Sportbeleid en activering.xlsx | B31: T51 | C31: Sportbeleid en activering | D31: L | E31: 548740.44 | F31: 549642 | G31: 559951 | H31: 570664 | J31: L | K31: =Recap!#REF! -> #REF! | L31: =Recap!E28 -> 689486.75 | M31: =Recap!F28 -> 684695 | N31: =Recap!G28 -> 695336 | P31: =K31-E31 -> #REF! | Q31: =L31-F31 -> 139844.75 | R31: =M31-G31 -> 124744 | S31: =N31-H31 -> 124672
A32: T52 Sportaccommodaties.xlsx | B32: T52 | C32: Sportaccommodaties | D32: L | E32: 2458176.2 | F32: 2507208.6 | G32: 2525720.8 | H32: 2479547.6 | J32: L | K32: =Recap!#REF! -> #REF! | L32: =Recap!E29 -> 2533362.2 | M32: =Recap!F29 -> 2615409 | N32: =Recap!G29 -> 2576630 | P32: =K32-E32 -> #REF! | Q32: =L32-F32 -> 26153.567 | R32: =M32-G32 -> 89688.198 | S32: =N32-H32 -> 97082.449
A33: T53 cultuurpresentatie,product,particip.xlsx | B33: T53 | C33: Cultuurproductie, presentatie en participatie | D33: L | E33: 899113.44 | F33: 932400.57 | G33: 950482.02 | H33: 985712.81 | J33: L | K33: =Recap!#REF! -> #REF! | L33: =Recap!E30 -> 886151.49 | M33: =Recap!F30 -> 840851.77 | N33: =Recap!G30 -> 871065.5 | P33: =K33-E33 -> #REF! | Q33: =L33-F33 -> -46249.078 | R33: =M33-G33 -> -109630.26 | S33: =N33-H33 -> -114647.31
A34: T54 Musea.xlsx | B34: T54 | C34: Musea | D34: L | E34: 129097 | F34: 134519 | G34: 140169 | H34: 146056 | J34: L | K34: =Recap!#REF! -> #REF! | L34: =Recap!E31 -> 134868 | M34: =Recap!F31 -> 140533 | N34: =Recap!G31 -> 145733 | P34: =K34-E34 -> #REF! | Q34: =L34-F34 -> 349 | R34: =M34-G34 -> 364 | S34: =N34-H34 -> -323
A35: T55 Cultureel erfgoed.xlsx | B35: T55 | C35: Cultureel erfgoed | D35: L | E35: 164125 | F35: 168781 | G35: 173579 | H35: 178525 | J35: L | K35: =Recap!#REF! -> #REF! | L35: =Recap!E32 -> 183726.12 | M35: =Recap!F32 -> 188904 | N35: =Recap!G32 -> 194166 | P35: =K35-E35 -> #REF! | Q35: =L35-F35 -> 14945.12 | R35: =M35-G35 -> 15325 | S35: =N35-H35 -> 15641
A36: T56 Media.xlsx | B36: T56 | C36: Media | D36: L | E36: 864942.48 | F36: 895029.96 | G36: 926371.59 | H36: 959024.14 | J36: L | K36: =Recap!#REF! -> #REF! | L36: =Recap!E33 -> 1007683.7 | M36: =Recap!F33 -> 949093.35 | N36: =Recap!G33 -> 964852.89 | P36: =K36-E36 -> #REF! | Q36: =L36-F36 -> 112653.77 | R36: =M36-G36 -> 22721.761 | S36: =N36-H36 -> 5828.7521 | U36: W01-2025 | V36: 100000 | W36: 100000
A37: T57 openbaar groen,(openlucht) recreatie.xlsx | B37: T57 | C37: Openbaar groen en (openlucht) recreatie | D37: L | E37: 3025219.6 | F37: 3198338.7 | G37: 3351719.5 | H37: 3393401 | J37: L | K37: =Recap!#REF! -> #REF! | L37: =Recap!E34 -> 3759810.8 | M37: =Recap!F34 -> 3514527.3 | N37: =Recap!G34 -> 3617129.2 | P37: =K37-E37 -> #REF! | Q37: =L37-F37 -> 561472.16 | R37: =M37-G37 -> 162807.78 | S37: =N37-H37 -> 223728.23
A38: T61 samenkracht en burgerparticipatie.xlsx | B38: T61 | C38: Samenkracht en burgerparticipatie | D38: L | E38: 3173329 | F38: 3238292 | G38: 3354555 | H38: 3475577 | J38: L | K38: =Recap!#REF! -> #REF! | L38: =Recap!E35 -> 4909998.1 | M38: =Recap!F35 -> 3579688.2 | N38: =Recap!G35 -> 3705656.9 | P38: =K38-E38 -> #REF! | Q38: =L38-F38 -> 1671706.1 | R38: =M38-G38 -> 225133.25 | S38: =N38-H38 -> 230079.92
A39: T62 2 toegang en eerstelijnsvoorzieningen Jeugd.xlsx | B39: T622 | C39: Toegang en eerstelijnsvoorzieningen jeugd | D39: L | E39: 1379590 | F39: 1435560 | G39: 1493810 | H39: 1554470 | J39: L | K39: =Recap!#REF! -> #REF! | L39: =Recap!E36 -> #REF! | M39: =Recap!F36 -> #REF! | N39: =Recap!G36 -> #REF! | P39: =K39-E39 -> #REF! | Q39: =L39-F39 -> #REF! | R39: =M39-G39 -> #REF! | S39: =N39-H39 -> #REF!
A40: T62 3 toegang en eerstelijnsvoorzieningen Integraal.xlsx | B40: T623 | C40: Toegang en eerstelijnsvoorzieningen integraal | D40: L | E40: 1992298 | F40: 2072186 | G40: 2155292 | H40: 2216718 | J40: L | K40: =Recap!#REF! -> #REF! | L40: =Recap!E37 -> #REF! | M40: =Recap!F37 -> #REF! | N40: =Recap!G37 -> #REF! | P40: =K40-E40 -> #REF! | Q40: =L40-F40 -> #REF! | R40: =M40-G40 -> #REF! | S40: =N40-H40 -> #REF!
A41: T63 inkomensregelingen.xlsx | B41: T63 | C41: Inkomensregelingen | D41: L | E41: 9531583.8 | F41: 9605131 | G41: 9595897 | H41: 9674473 | J41: L | K41: =Recap!#REF! -> #REF! | L41: =Recap!E38 -> 11332734 | M41: =Recap!F38 -> 10727447 | N41: =Recap!G38 -> 10709251 | P41: =K41-E41 -> #REF! | Q41: =L41-F41 -> 1727602.9 | R41: =M41-G41 -> 1131550 | S41: =N41-H41 -> 1034778
...

Sheet Recap
A1: TAAKVELDENRAMING 2027 (NIEUW) | J1: TAAKVELDENRAMING 2026 (OUD) | R1: CODA | X1: VERSCHIL
A2: Taakveld | C2: Omschrijving | E2: 2026 | F2: 2027 | G2: 2028 | H2: 2029 | I2: 2030 | J2: 2026 | K2: verschil 2026 | L2: 2027 | M2: verschil 2027 | N2: 2028 | O2: verschil 2028 | P2: 2029 | Q2: verschil 2029 | R2: Taakveld | S2: Begroot 2026 | T2: Begroot 2027 | U2: Begroot 2028 | V2: Begroot 2029 | X2: Begroot 2026 | Y2: Begroot 2027 | Z2: Begroot 2028 | AA2: Begroot 2029
A3: T01 bestuur en ondersteuning.xlsx | B3: T01 | C3: Bestuur | D3: L | E3: ='T01'!K59 -> 4096256.6 | F3: ='T01'!L59 -> 3519006 | G3: ='T01'!M59 -> 3429319.8 | H3: ='T01'!N59 -> 3483441.6 | I3: ='T01'!O59 -> 3375675.2 | J3: 3623256.6 | K3: =J3-E3 -> -473000 | L3: 3527749.7 | M3: =L3-F3 -> 8743.6455 | N3: 3455653.2 | O3: =N3-G3 -> 26333.33 | P3: 3530153.9 | Q3: =P3-H3 -> 46712.333 | R3: 01 - Bestuur | S3: 3773257 | T3: 3527750 | U3: 3455654 | V3: 3530154 | X3: =S3-E3 -> -322999.6 | Y3: =T3-F3 -> 8743.9572 | Z3: =U3-G3 -> 26334.172 | AA3: =V3-H3 -> 46712.44
A4: T02 burgerzaken.xlsx | B4: T02 | C4: Burgerzaken | D4: L | E4: ='T02'!K41 -> 1279045.3 | F4: ='T02'!L41 -> 1306068.9 | G4: ='T02'!M41 -> 1349138.8 | H4: ='T02'!N41 -> 1393851.2 | I4: ='T02'!O41 -> 1439152.7 | J4: 1279045.3 | K4: =J4-E4 -> 0 | L4: 1310633.5 | M4: =L4-F4 -> 4564.615 | N4: 1360649.3 | O4: =N4-G4 -> 11510.507 | P4: 1413091.3 | Q4: =P4-H4 -> 19240.098 | R4: 02 - Burgerzaken | S4: 1279045 | T4: 1310634 | U4: 1360649 | V4: 1413091 | X4: =S4-E4 -> -0.28 | Y4: =T4-F4 -> 4565.085 | Z4: =U4-G4 -> 11510.245 | AA4: =V4-H4 -> 19239.832
A5: T03 beheer overige gebouwen en gronden.xlsx | B5: T03 | C5: Beheer overige gebouwen en gronden | D5: L | E5: ='T03'!K47 -> 653245.52 | F5: ='T03'!L47 -> 339365.95 | G5: ='T03'!M47 -> 348755.73 | H5: ='T03'!N47 -> 358458.63 | I5: ='T03'!O47 -> 349646 | J5: 341264.52 | K5: =J5-E5 -> -311981 | L5: 340102.95 | M5: =L5-F5 -> 737 | N5: 350926.73 | O5: =N5-G5 -> 2171 | P5: 362180.63 | Q5: =P5-H5 -> 3722 | R5: 03 - Beheer overige gebouwen en gronden | S5: 516264 | T5: 340103 | U5: 350927 | V5: 362181 | X5: =S5-E5 -> -136981.52 | Y5: =T5-F5 -> 737.04656 | Z5: =U5-G5 -> 2171.2663 | AA5: =V5-H5 -> 3722.3691
A6: T04 bedrijf.xlsx | B6: T04B | C6: Overhead - 1 bedrijfsvoering | D6: L | E6: =T04B!K53 -> 3325272.6 | F6: =T04B!L53 -> 3607658.3 | G6: =T04B!M53 -> 3180175.8 | H6: =T04B!N53 -> 3219679.8 | I6: =T04B!O53 -> 2851594.3 | J6: 3325272.6 | K6: =J6-E6 -> 0 | L6: 3610113.2 | M6: =L6-F6 -> 2454.8389 | N6: 3180589.5 | O6: =N6-G6 -> 413.74496 | P6: 3217938.9 | Q6: =P6-H6 -> -1740.916 | X6: =S6-E6 -> -3325272.6 | Y6: =T6-F6 -> -3607658.3 | Z6: =U6-G6 -> -3180175.8 | AA6: =V6-H6 -> -3219679.8
A7: T04 loon.xlsx | B7: T04L | C7: Overhead - 2 loonkosten | D7: L | E7: =T04L!K52 -> 11367751 | F7: =T04L!L52 -> 11709325 | G7: =T04L!M52 -> 12465644 | H7: =T04L!N52 -> 12994586 | I7: =T04L!O52 -> 13679959 | J7: 11509751 | K7: =J7-E7 -> 142000 | L7: 12108487 | M7: =L7-F7 -> 399162.46 | N7: 12596822 | O7: =N7-G7 -> 131178.14 | P7: 13225641 | Q7: =P7-H7 -> 231055.77 | R7: 04 - Overhead | S7: 14936461 | T7: 15479335 | U7: 15612493 | V7: 16278708 | X7: =S7-E7 -> 3568710.4 | Y7: =T7-F7 -> 3770010.4 | Z7: =U7-G7 -> 3146849 | AA7: =V7-H7 -> 3284122.4
A8: T04 werf.xlsx | B8: T04W | C8: Overhead - 3 werf en vervoermiddelen | D8: L | E8: =T04W!K41 -> 0 | F8: =T04W!L41 -> 0 | G8: =T04W!M41 -> 0 | H8: =T04W!N41 -> 0 | I8: =T04W!O41 -> 0 | J8: 0 | K8: =J8-E8 -> 0 | L8: 0 | M8: =L8-F8 -> 0 | N8: 0 | O8: =N8-G8 -> 0 | P8: 0 | Q8: =P8-H8 -> 0 | X8: =S8-E8 -> 0 | Y8: =T8-F8 -> 0 | Z8: =U8-G8 -> 0 | AA8: =V8-H8 -> 0
A9: T05 Treasury.xlsx | B9: T05 | C9: Treasury | D9: L | E9: ='T05'!K29 -> 204771 | F9: ='T05'!L29 -> 629078 | G9: ='T05'!M29 -> 1083905 | H9: ='T05'!N29 -> 1780521.3 | I9: ='T05'!O29 -> 18000 | J9: 204771 | K9: =J9-E9 -> 0 | L9: 629078 | M9: =L9-F9 -> 0 | N9: 1083905 | O9: =N9-G9 -> 0 | P9: 1780521.3 | Q9: =P9-H9 -> 0 | R9: 05 - Treasury | S9: 204771 | T9: 629078 | U9: 733905 | V9: 1430521 | X9: =S9-E9 -> 0 | Y9: =T9-F9 -> 0 | Z9: =U9-G9 -> -350000 | AA9: =V9-H9 -> -350000.33
A10: T06 1 OZB Woningen.xlsx | B10: T061 | C10: OZB Woningen | D10: L | E10: ='T061'!K27 -> 172088 | F10: ='T061'!L27 -> 177644 | G10: ='T061'!M27 -> 183043 | H10: ='T061'!N27 -> 188616 | I10: ='T061'!O27 -> 188017 | J10: 172088 | K10: =J10-E10 -> 0 | L10: 178088 | M10: =L10-F10 -> 444 | N10: 184323 | O10: =N10-G10 -> 1280 | P10: 190801 | Q10: =P10-H10 -> 2185 | R10: 061 - OZB woningen | S10: 172088 | T10: 178088 | U10: 184323 | V10: 190801 | X10: =S10-E10 -> 0 | Y10: =T10-F10 -> 444 | Z10: =U10-G10 -> 1280 | AA10: =V10-H10 -> 2185
A11: T06 2 OZB Niet-Woningen.xlsx | B11: T062 | C11: OZB Niet woningen | D11: L | E11: ='T062'!K29 -> 130667 | F11: ='T062'!L29 -> 135042 | G11: ='T062'!M29 -> 139255 | H11: ='T062'!N29 -> 143607 | I11: ='T062'!O29 -> 143871 | J11: 130667 | K11: =J11-E11 -> 0 | L11: 135401 | M11: =L11-F11 -> 359 | N11: 140324 | O11: =N11-G11 -> 1069 | P11: 145445 | Q11: =P11-H11 -> 1838 | R11: 062 - OZB niet-woningen | S11: 130667 | T11: 135401 | U11: 140324 | V11: 145445 | X11: =S11-E11 -> 0 | Y11: =T11-F11 -> 359 | Z11: =U11-G11 -> 1069 | AA11: =V11-H11 -> 1838
A12: T06 4 Belastingen overig.xlsx | B12: T064 | C12: Belastingen overig | D12: L | E12: ='T064'!K29 -> 65986 | F12: ='T064'!L29 -> 68757 | G12: ='T064'!M29 -> 71301 | H12: ='T064'!N29 -> 73939 | I12: ='T064'!O29 -> 76675 | J12: 65986 | K12: =J12-E12 -> 0 | L12: 69021 | M12: =L12-F12 -> 264 | N12: 72196 | O12: =N12-G12 -> 895 | P12: 75517 | Q12: =P12-H12 -> 1578 | R12: 064 - Belastingen overig | S12: 65986 | T12: 69021 | U12: 72196 | V12: 75517 | X12: =S12-E12 -> 0 | Y12: =T12-F12 -> 264 | Z12: =U12-G12 -> 895 | AA12: =V12-H12 -> 1578
A13: T07 Gemeentefonds en overige rijksuitkeringen.xlsx | B13: T07 | C13: Alg. uitkeringen en ov uitkeringen gemeentefonds | D13: L | E13: ='T07'!K34 -> 5780 | F13: ='T07'!L34 -> 5901 | G13: ='T07'!M34 -> 6037 | H13: ='T07'!N34 -> 6176 | I13: ='T07'!O34 -> 6318 | J13: 5780 | K13: =J13-E13 -> 0 | L13: 5907 | M13: =L13-F13 -> 6 | N13: 6037 | O13: =N13-G13 -> 0 | P13: 6170 | Q13: =P13-H13 -> -6 | R13: 07 - Alg.uitkering en ov.uitk.Gemeentefonds | S13: 5780 | T13: 5907 | U13: 6037 | V13: 6170 | X13: =S13-E13 -> 0 | Y13: =T13-F13 -> 6 | Z13: =U13-G13 -> 0 | AA13: =V13-H13 -> -6
A14: T08 Overige baten en lasten.xlsx | B14: T08 | C14: Overige baten en lasten | D14: L | E14: ='T08'!K40 -> 594431.35 | F14: ='T08'!L40 -> 233854 | G14: ='T08'!M40 -> 238228 | H14: ='T08'!N40 -> 242703 | I14: ='T08'!O40 -> 247281 | J14: 594431.35 | K14: =J14-E14 -> 0 | L14: 578621.87 | M14: =L14-F14 -> 344767.87 | N14: -3634954.7 | O14: =N14-G14 -> -3873182.7 | P14: -3989678.2 | Q14: =P14-H14 -> -4232381.2 | R14: 08 - Overige baten en lasten | S14: 703750 | T14: 740749 | U14: 1699388 | V14: 1776715 | X14: =S14-E14 -> 109318.65 | Y14: =T14-F14 -> 506895 | Z14: =U14-G14 -> 1461160 | AA14: =V14-H14 -> 1534012
A15: T09 Vennootschapsbelasting.xlsx | B15: T09 | C15: Vennootschapsbelasting | D15: L | E15: ='T09'!K40 -> 11400 | F15: ='T09'!L40 -> 11400 | G15: ='T09'!M40 -> 11400 | H15: ='T09'!N40 -> 11400 | I15: ='T09'!O40 -> 11400 | J15: 11400 | K15: =J15-E15 -> 0 | L15: 11400 | M15: =L15-F15 -> 0 | N15: 11400 | O15: =N15-G15 -> 0 | P15: 11400 | Q15: =P15-H15 -> 0 | R15: 09 - Vennootschapsbelasting (VPB) | S15: 11400 | T15: 11400 | U15: 11400 | V15: 11400 | X15: =S15-E15 -> 0 | Y15: =T15-F15 -> 0 | Z15: =U15-G15 -> 0 | AA15: =V15-H15 -> 0
A16: T010 Mutaties Reserve.xlsx | B16: T010 | C16: Mutaties reserves | D16: L | E16: ='T010'!K22 -> 905588 | F16: ='T010'!L22 -> 471829 | G16: ='T010'!M22 -> 438368 | H16: ='T010'!N22 -> 373260 | I16: ='T010'!O22 -> 0 | J16: 590588 | K16: =J16-E16 -> -315000 | L16: 471829 | M16: =L16-F16 -> 0 | N16: 438368 | O16: =N16-G16 -> 0 | P16: 373260 | Q16: =P16-H16 -> 0 | R16: 010 - Mutaties reserves | S16: 590588 | T16: 471829 | U16: 438368 | V16: 373260 | X16: =S16-E16 -> -315000 | Y16: =T16-F16 -> 0 | Z16: =U16-G16 -> 0 | AA16: =V16-H16 -> 0
A17: T011 Resultaat rekening baten en lasten.xlsx | B17: T011 | C17: Resultaat van de rekening van baten en lasten | D17: L | E17: ='T011'!K37 -> 0 | F17: ='T011'!L37 -> 0 | G17: ='T011'!M37 -> 0 | H17: ='T011'!N37 -> 0 | I17: ='T011'!O37 -> 0 | J17: 0 | K17: =J17-E17 -> 0 | L17: 0 | M17: =L17-F17 -> 0 | N17: 0 | O17: =N17-G17 -> 0 | P17: 0 | Q17: =P17-H17 -> 0 | S17: 0 | T17: 0 | U17: 0 | V17: 0 | X17: =S17-E17 -> 0 | Y17: =T17-F17 -> 0 | Z17: =U17-G17 -> 0 | AA17: =V17-H17 -> 0
A18: T11 crisisbeheersing en brandweer.xlsx | B18: T11 | C18: Crisisbeheersing en brandweer | D18: L | E18: ='T11'!K46 -> 2088526.5 | F18: ='T11'!L46 -> 2264477.9 | G18: ='T11'!M46 -> 2326060.9 | H18: ='T11'!N46 -> 2396344 | I18: ='T11'!O46 -> 2406801.2 | J18: 2088526.5 | K18: =J18-E18 -> 0 | L18: 2270039.7 | M18: =L18-F18 -> 5561.7831 | N18: 2341425.4 | O18: =N18-G18 -> 15364.571 | P18: 2422153.4 | Q18: =P18-H18 -> 25809.367 | R18: 11 - Crisisbeheersing en brandweer | S18: 2088527 | T18: 2270040 | U18: 2341426 | V18: 2422153 | X18: =S18-E18 -> 0.46765 | Y18: =T18-F18 -> 5562.0603 | Z18: =U18-G18 -> 15365.149 | AA18: =V18-H18 -> 25809.016
A19: T12 openbare orde en veiligheid.xlsx | B19: T12 | C19: Openbare orde en veiligheid | D19: L | E19: ='T12'!K55 -> 2005361.2 | F19: ='T12'!L55 -> 1932160.2 | G19: ='T12'!M55 -> 1999201.4 | H19: ='T12'!N55 -> 2061561.9 | I19: ='T12'!O55 -> 2134460.1 | J19: 1893861.2 | K19: =J19-E19 -> -111500 | L19: 1924507.1 | M19: =L19-F19 -> -7653.1138 | N19: 2008492.2 | O19: =N19-G19 -> 9290.8087 | P19: 2095062 | Q19: =P19-H19 -> 33500.116 | R19: 12 - Openbare orde en veiligheid | S19: 1903861 | T19: 1934507 | U19: 2016493 | V19: 2095063 | X19: =S19-E19 -> -101500.18 | Y19: =T19-F19 -> 2346.7628 | Z19: =U19-G19 -> 17291.617 | AA19: =V19-H19 -> 33501.089
A20: T21 Verkeer en vervoer.xlsx | B20: T21 | C20: Verkeer en vervoer | D20: L | E20: ='T21'!K67 -> 4152536.9 | F20: ='T21'!L67 -> 4859110.9 | G20: ='T21'!M67 -> 5275649.8 | H20: ='T21'!N67 -> 5910454 | I20: ='T21'!O67 -> 4063920.3 | J20: 4112749.9 | K20: =J20-E20 -> -39787 | L20: 4863397.2 | M20: =L20-F20 -> 4286.3 | N20: 5284607.8 | O20: =N20-G20 -> 8958 | P20: 5924632.9 | Q20: =P20-H20 -> 14178.92 | R20: 21 - Verkeer en vervoer | S20: 4112752 | T20: 4863396 | U20: 5259611 | V20: 5714629 | X20: =S20-E20 -> -39784.884 | Y20: =T20-F20 -> 4285.081 | Z20: =U20-G20 -> -16038.753 | AA20: =V20-H20 -> -195825.01
A21: T22 parkeren.xlsx | B21: T22 | C21: Parkeren | D21: L | E21: ='T22'!K32 -> 89294.891 | F21: ='T22'!L32 -> 90577.142 | G21: ='T22'!M32 -> 91996.267 | H21: ='T22'!N32 -> 163450.07 | I21: ='T22'!O32 -> 89595.837 | J21: 89294.891 | K21: =J21-E21 -> 0 | L21: 90630.393 | M21: =L21-F21 -> 53.250559 | N21: 91995.242 | O21: =N21-G21 -> -1.0247494 | P21: 163394.9 | Q21: =P21-H21 -> -55.174923 | R21: 22 - Parkeren | S21: 89295 | T21: 90631 | U21: 91995 | V21: 163395 | X21: =S21-E21 -> 0.10892786 | Y21: =T21-F21 -> 53.857895 | Z21: =U21-G21 -> -1.2668785 | AA21: =V21-H21 -> -55.070632
A22: T25 openbaar vervoer.xlsx | B22: T25 | C22: Openbaar vervoer | D22: L | E22: ='T25'!K34 -> 99454.81 | F22: ='T25'!L34 -> 101593.02 | G22: ='T25'!M34 -> 103963.27 | H22: ='T25'!N34 -> 106389.34 | I22: ='T25'!O34 -> 108873.65 | J22: 99454.81 | K22: =J22-E22 -> 0 | L22: 101698.4 | M22: =L22-F22 -> 105.38 | N22: 103996.48 | O22: =N22-G22 -> 33.21 | P22: 106345.54 | Q22: =P22-H22 -> -43.8 | R22: 25 - Openbaar vervoer | S22: 99455 | T22: 101698 | U22: 103996 | V22: 106346 | X22: =S22-E22 -> 0.19 | Y22: =T22-F22 -> 104.98 | Z22: =U22-G22 -> 32.73 | AA22: =V22-H22 -> -43.34
A23: T31 economische ontwikkeling.xlsx | B23: T31 | C23: Economische ontwikkeling | D23: L | E23: ='T31'!K43 -> 1355577.6 | F23: ='T31'!L43 -> 1122696.5 | G23: ='T31'!M43 -> 1152490.1 | H23: ='T31'!N43 -> 1182934.2 | I23: ='T31'!O43 -> 1216184.8 | J23: 1105577.6 | K23: =J23-E23 -> -250000 | L23: 1124466.9 | M23: =L23-F23 -> 1770.39 | N23: 1157510.1 | O23: =N23-G23 -> 5020 | P23: 1191437.7 | Q23: =P23-H23 -> 8503.58 | R23: 31 - Economische ontwikkeling | S23: 1355578 | T23: 1124467 | U23: 1157510 | V23: 1191438 | X23: =S23-E23 -> 0.44 | Y23: =T23-F23 -> 1770.47 | Z23: =U23-G23 -> 5019.89 | AA23: =V23-H23 -> 8503.8432
A24: T33 bedrijfsloket en bedrijfsregelingen.xlsx | B24: T33 | C24: Bedrijvenloket en bedrijvenregeling | D24: L | E24: ='T33'!K39 -> 41976.024 | F24: ='T33'!L39 -> 43502.504 | G24: ='T33'!M39 -> 44931.464 | H24: ='T33'!N39 -> 46407.928 | I24: ='T33'!O39 -> 47935.919 | J24: 41976.024 | K24: =J24-E24 -> 0 | L24: 43634.504 | M24: =L24-F24 -> 132 | N24: 45364.464 | O24: =N24-G24 -> 433 | P24: 47167.928 | Q24: =P24-H24 -> 760 | R24: 33 - Bedrijvenloket en bedrijfsregelingen | S24: 41976 | T24: 43635 | U24: 45364 | V24: 47168 | X24: =S24-E24 -> -0.024 | Y24: =T24-F24 -> 132.49562 | Z24: =U24-G24 -> 432.53555 | AA24: =V24-H24 -> 760.07211
A25: T34 economische promotie.xlsx | B25: T34 | C25: Economische promotie | D25: L | E25: ='T34'!K55 -> 517402.83 | F25: ='T34'!L55 -> 526952.76 | G25: ='T34'!M55 -> 536047.59 | H25: ='T34'!N55 -> 545414.76 | I25: ='T34'!O55 -> 554987.85 | J25: 517402.83 | K25: =J25-E25 -> 0 | L25: 527714.76 | M25: =L25-F25 -> 762 | N25: 538500.59 | O25: =N25-G25 -> 2453 | P25: 549700.76 | Q25: =P25-H25 -> 4286 | R25: 34 - Economische promotie | S25: 517403 | T25: 527715 | U25: 538501 | V25: 549701 | X25: =S25-E25 -> 0.173 | Y25: =T25-F25 -> 762.23582 | Z25: =U25-G25 -> 2453.4132 | AA25: =V25-H25 -> 4286.2377
A26: T42 onderwijshuisvesting.xlsx | B26: T42 | C26: Onderwijshuisvesting | D26: L | E26: ='T42'!K53 -> 1735325.4 | F26: ='T42'!L53 -> 1740867.3 | G26: ='T42'!M53 -> 3159300.5 | H26: ='T42'!N53 -> 3420717.7 | I26: ='T42'!O53 -> 403035 | J26: 1735325.4 | K26: =J26-E26 -> 0 | L26: 1741492.3 | M26: =L26-F26 -> 625 | N26: 2475764.5 | O26: =N26-G26 -> -683536 | P26: 2598887.7 | Q26: =P26-H26 -> -821830 | R26: 42 - Onderwijshuisvesting | S26: 1735326 | T26: 1741492 | U26: 3154117 | V26: 2977241 | X26: =S26-E26 -> 0.64467532 | Y26: =T26-F26 -> 624.68921 | Z26: =U26-G26 -> -5183.4693 | AA26: =V26-H26 -> -443476.73
A27: T43 onderwijsbeleid en leerlingenzaken.xlsx | B27: T43 | C27: Onderwijsbeleid en leerlingenzaken | D27: L | E27: ='T43'!K43 -> 1829738.2 | F27: ='T43'!L43 -> 1882242 | G27: ='T43'!M43 -> 1908620 | H27: ='T43'!N43 -> 1931690 | I27: ='T43'!O43 -> 2008399 | J27: 1829738.2 | K27: =J27-E27 -> 0 | L27: 1886486 | M27: =L27-F27 -> 4244 | N27: 1923432 | O27: =N27-G27 -> 14812 | P27: 1984502 | Q27: =P27-H27 -> 52812 | R27: 43 - Onderwijsbeleid en leerlingzaken | S27: 1829738 | T27: 1886486 | U27: 1923432 | V27: 1984502 | X27: =S27-E27 -> -0.23 | Y27: =T27-F27 -> 4244 | Z27: =U27-G27 -> 14812 | AA27: =V27-H27 -> 52812
A28: T51 Sportbeleid en activering.xlsx | B28: T51 | C28: Sportbeleid en activering | D28: L | E28: ='T51'!K39 -> 689486.75 | F28: ='T51'!L39 -> 684695 | G28: ='T51'!M39 -> 695336 | H28: ='T51'!N39 -> 706331 | I28: ='T51'!O39 -> 712997 | J28: 673486.75 | K28: =J28-E28 -> -16000 | L28: 685654 | M28: =L28-F28 -> 959 | N28: 698347 | O28: =N28-G28 -> 3011 | P28: 711564 | Q28: =P28-H28 -> 5233 | R28: 51 - Sportbeleid en activering | S28: 689487 | T28: 685654 | U28: 698347 | V28: 711564 | X28: =S28-E28 -> 0.25 | Y28: =T28-F28 -> 959 | Z28: =U28-G28 -> 3011 | AA28: =V28-H28 -> 5233
A29: T52 Sportaccommodaties.xlsx | B29: T52 | C29: Sportaccommodaties | D29: L | E29: ='T52'!K64 -> 2533362.2 | F29: ='T52'!L64 -> 2615409 | G29: ='T52'!M64 -> 2576630 | H29: ='T52'!N64 -> 2851315.7 | I29: ='T52'!O64 -> 1652621.5 | J29: 2521625.2 | K29: =J29-E29 -> -11737 | L29: 2616704.4 | M29: =L29-F29 -> 1295.3534 | N29: 2587140 | O29: =N29-G29 -> 10510.026 | P29: 2737816 | Q29: =P29-H29 -> -113499.7 | R29: 52 - Sportaccommodaties | S29: 2521626 | T29: 2616705 | U29: 2587138 | V29: 2636159 | X29: =S29-E29 -> -11736.195 | Y29: =T29-F29 -> 1295.9799 | Z29: =U29-G29 -> 10507.979 | AA29: =V29-H29 -> -215156.73
A30: T53 cultuurpresentatie,product,particip.xlsx | B30: T53 | C30: Cultuurproductie, presentatie en participatie | D30: L | E30: ='T53'!K50 -> 886151.49 | F30: ='T53'!L50 -> 840851.77 | G30: ='T53'!M50 -> 871065.5 | H30: ='T53'!N50 -> 902317.91 | I30: ='T53'!O50 -> 934626.78 | J30: 809151.49 | K30: =J30-E30 -> -77000 | L30: 843632.05 | M30: =L30-F30 -> 2780.2789 | N30: 879563.4 | O30: =N30-G30 -> 8497.9013 | P30: 917008.93 | Q30: =P30-H30 -> 14691.012 | R30: 53 - Cultuurpresentatie,-productie,-participatie | S30: 809152 | T30: 843632 | U30: 879563 | V30: 917009 | X30: =S30-E30 -> -76999.492 | Y30: =T30-F30 -> 2780.2305 | Z30: =U30-G30 -> 8497.4978 | AA30: =V30-H30 -> 14691.085
A31: T54 Musea.xlsx | B31: T54 | C31: Musea | D31: L | E31: ='T54'!K34 -> 134868 | F31: ='T54'!L34 -> 140533 | G31: ='T54'!M34 -> 145733 | H31: ='T54'!N34 -> 151125 | I31: ='T54'!O34 -> 156717 | J31: 134868 | K31: =J31-E31 -> 0 | L31: 141072 | M31: =L31-F31 -> 539 | N31: 147562 | O31: =N31-G31 -> 1829 | P31: 154350 | Q31: =P31-H31 -> 3225 | R31: 54 - Musea | S31: 134868 | T31: 141072 | U31: 147562 | V31: 154350 | X31: =S31-E31 -> 0 | Y31: =T31-F31 -> 539 | Z31: =U31-G31 -> 1829 | AA31: =V31-H31 -> 3225
A32: T55 Cultureel erfgoed.xlsx | B32: T55 | C32: Cultureel erfgoed | D32: L | E32: ='T55'!K33 -> 183726.12 | F32: ='T55'!L33 -> 188904 | G32: ='T55'!M33 -> 194166 | H32: ='T55'!N33 -> 199583 | I32: ='T55'!O33 -> 205158 | J32: 183726.12 | K32: =J32-E32 -> 0 | L32: 189277 | M32: =L32-F32 -> 373 | N32: 195020 | O32: =N32-G32 -> 854 | P32: 200962 | Q32: =P32-H32 -> 1379 | R32: 55 - Cultureel erfgoed | S32: 183726 | T32: 189277 | U32: 195020 | V32: 200962 | X32: =S32-E32 -> -0.12 | Y32: =T32-F32 -> 373 | Z32: =U32-G32 -> 854 | AA32: =V32-H32 -> 1379
A33: T56 Media.xlsx | B33: T56 | C33: Media | D33: L | E33: ='T56'!K33 -> 1007683.7 | F33: ='T56'!L33 -> 949093.35 | G33: ='T56'!M33 -> 964852.89 | H33: ='T56'!N33 -> 980936.18 | I33: ='T56'!O33 -> 996641.18 | J33: 1007683.7 | K33: =J33-E33 -> 0 | L33: 923106.35 | M33: =L33-F33 -> -25987 | N33: 938853.89 | O33: =N33-G33 -> -25999 | P33: 954925.18 | Q33: =P33-H33 -> -26011 | R33: 56 - Media | S33: 1033684 | T33: 949106 | U33: 964854 | V33: 980925 | X33: =S33-E33 -> 26000.271 | Y33: =T33-F33 -> 12.651615 | Z33: =U33-G33 -> 1.1057248 | AA33: =V33-H33 -> -11.178363
A34: T57 openbaar groen,(openlucht) recreatie.xlsx | B34: T57 | C34: Openbaar groen en (openlucht) recreatie | D34: L | E34: ='T57'!K46 -> 3759810.8 | F34: ='T57'!L46 -> 3514527.3 | G34: ='T57'!M46 -> 3617129.2 | H34: ='T57'!N46 -> 3718653.6 | I34: ='T57'!O46 -> 3829327.5 | J34: 3691899.8 | K34: =J34-E34 -> -67911 | L34: 3522446.8 | M34: =L34-F34 -> 7919.4627 | N34: 3650337.2 | O34: =N34-G34 -> 33207.992 | P34: 3776788.8 | Q34: =P34-H34 -> 58135.184 | R34: 57 - Openbaar groen en recreatie | S34: 3691898 | T34: 3522446 | U34: 3645338 | V34: 3766788 | X34: =S34-E34 -> -67912.817 | Y34: =T34-F34 -> 7918.6754 | Z34: =U34-G34 -> 28208.78 | AA34: =V34-H34 -> 48134.412
A35: T61 samenkracht en burgerparticipatie.xlsx | B35: T61 | C35: Samenkracht en burgerparticipatie | D35: L | E35: ='T61'!K61 -> 4909998.1 | F35: ='T61'!L61 -> 3579688.2 | G35: ='T61'!M61 -> 3705656.9 | H35: ='T61'!N61 -> 3824034.5 | I35: ='T61'!O61 -> 3868944.1 | J35: 3409998.1 | K35: =J35-E35 -> -1500000 | L35: 3590552.2 | M35: =L35-F35 -> 10864 | N35: 3731387.9 | O35: =N35-G35 -> 25731 | P35: 3865906.5 | Q35: =P35-H35 -> 41872 | R35: 61 - Samenkracht en burgerparticipatie | S35: 4909998 | T35: 3590551 | U35: 3731387 | V35: 3865906 | X35: =S35-E35 -> -0.057929775 | Y35: =T35-F35 -> 10862.751 | Z35: =U35-G35 -> 25730.083 | AA35: =V35-H35 -> 41871.52
A36: T62 2 toegang en eerstelijnsvoorzieningen Jeugd.xlsx | B36: T622 | C36: Toegang en eerstelijnsvoorzieningen jeugd | D36: L | E36: =#REF! -> #REF! | F36: =#REF! -> #REF! | G36: =#REF! -> #REF! | H36: =#REF! -> #REF! | I36: =#REF! -> #REF! | J36: 2205080 | K36: =J36-E36 -> #REF! | L36: 2399654 | M36: =L36-F36 -> #REF! | N36: 2316517 | O36: =N36-G36 -> #REF! | P36: 2413629 | Q36: =P36-H36 -> #REF! | R36: 622 - Toegang en eerstelijnsvoorzieningen Jeugd | S36: 2205080 | T36: 2399654 | U36: 2316517 | V36: 2413629 | X36: =S36-E36 -> #REF! | Y36: =T36-F36 -> #REF! | Z36: =U36-G36 -> #REF! | AA36: =V36-H36 -> #REF!
A37: T62 3 toegang en eerstelijnsvoorzieningen Integraal.xlsx | B37: T623 | C37: Toegang en eerstelijnsvoorzieningen integraal | D37: L | E37: =#REF! -> #REF! | F37: =#REF! -> #REF! | G37: =#REF! -> #REF! | H37: =#REF! -> #REF! | I37: =#REF! -> #REF! | J37: 667719.3 | K37: =J37-E37 -> #REF! | L37: 707207.52 | M37: =L37-F37 -> #REF! | N37: 709141.94 | O37: =N37-G37 -> #REF! | P37: 734203.34 | Q37: =P37-H37 -> #REF! | R37: 623 - Toegang en eerstelijnsvoorzieningen Integraal | S37: 667719 | T37: 707208 | U37: 709142 | V37: 734203 | X37: =S37-E37 -> #REF! | Y37: =T37-F37 -> #REF! | Z37: =U37-G37 -> #REF! | AA37: =V37-H37 -> #REF!
A38: T63 inkomensregelingen.xlsx | B38: T63 | C38: Inkomensregelingen | D38: L | E38: ='T63'!K58 -> 11332734 | F38: ='T63'!L58 -> 10727447 | G38: ='T63'!M58 -> 10709251 | H38: ='T63'!N58 -> 10814879 | I38: ='T63'!O58 -> 10798998 | J38: 10616557 | K38: =J38-E38 -> -716177 | L38: 10621796 | M38: =L38-F38 -> -105651 | N38: 10732811 | O38: =N38-G38 -> 23560 | P38: 10855355 | Q38: =P38-H38 -> 40476 | R38: 63 - Inkomensregelingen | S38: 10616557 | T38: 10621796 | U38: 10732811 | V38: 10855355 | X38: =S38-E38 -> -716176.93 | Y38: =T38-F38 -> -105651 | Z38: =U38-G38 -> 23560 | AA38: =V38-H38 -> 40476
A39: T64 begeleide participatie.xlsx | B39: T64 | C39: WSW en beschut werk | D39: L | E39: =#REF! -> #REF! | F39: =#REF! -> #REF! | G39: =#REF! -> #REF! | H39: =#REF! -> #REF! | I39: =#REF! -> #REF! | J39: 3559883 | K39: =J39-E39 -> #REF! | L39: 3395552 | M39: =L39-F39 -> #REF! | N39: 3240412 | O39: =N39-G39 -> #REF! | P39: 3240609 | Q39: =P39-H39 -> #REF! | R39: 64 - Begeleide participatie | S39: 3560789 | T39: 3396527 | U39: 3241456 | V39: 3241723 | X39: =S39-E39 -> #REF! | Y39: =T39-F39 -> #REF! | Z39: =U39-G39 -> #REF! | AA39: =V39-H39 -> #REF!
A40: T65 arbeidsparticipatie.xlsx | B40: T65 | C40: Arbeidsparticipatie | D40: L | E40: ='T65'!K45 -> 2733683 | F40: ='T65'!L45 -> 2265920 | G40: ='T65'!M45 -> 2295116 | H40: ='T65'!N45 -> 2392153 | I40: ='T65'!O45 -> 2449043 | J40: 2103368 | K40: =J40-E40 -> -630315 | L40: 2210941 | M40: =L40-F40 -> -54979 | N40: 2310500 | O40: =N40-G40 -> 15384 | P40: 2418846 | Q40: =P40-H40 -> 26693 | R40: 65 - Arbeidsparticipatie | S40: 2176536 | T40: 2270851 | U40: 2310500 | V40: 2418846 | X40: =S40-E40 -> -557146.98 | Y40: =T40-F40 -> 4931 | Z40: =U40-G40 -> 15384 | AA40: =V40-H40 -> 26693
...

Sheet T01
A1: Inhoudsopgave | Q1: 2024 | R1: 2025 | S1: 2026 | T1: 2027 | U1: 2028 | V1: 2029 | W1: 2030
D2: Programma | H2: 01. Algemeen bestuur | Q2: =+Indexering!G4 -> 1.037 | R2: =+Indexering!H4 -> 1.028 | S2: =+Indexering!I4 -> 1.026 | T2: =+Indexering!J4 -> 1.021 | U2: =+Indexering!K4 -> 1.023 | V2: =+Indexering!L4 -> 1.023 | W2: =+Indexering!M4 -> 1.023
Q3: =+Indexering!G5 -> 1.052 | R3: =+Indexering!H5 -> 1.049 | S3: =+Indexering!I5 -> 1.02 | T3: =+Indexering!J5 -> 1.042 | U3: =+Indexering!K5 -> 1.037 | V3: =+Indexering!L5 -> 1.037 | W3: =+Indexering!M5 -> 1.037
S4: =+Indexering!I6 -> 1.02282 | T4: =+Indexering!J6 -> 1.03213 | U4: =+Indexering!K6 -> 1.03042 | V4: =+Indexering!L6 -> 1.03042 | W4: =+Indexering!M6 -> 1.03042
D6: Taakveld | H6: T01 Bestuur en ondersteuning
D30: In te zetten middelen
D32: Lasten in € (+) | J32: 2025 | K32: 2026 | L32: 2027 | M32: 2028 | N32: 2029 | O32: 2030
D33: Raad en raadscommissies | J33: 97488 | K33: =K82 -> 104686 | L33: =L82 -> 96506 | M33: =M82 -> 98542 | N33: =N82 -> 100624 | O33: =O82 -> 102754
D34: Raadsfracties | J34: 7716.168 | K34: =K87 -> 7916.7884 | L34: =L87 -> 8083.0409 | M34: =M87 -> 8268.9509 | N34: =N87 -> 8459.1367 | O34: =O87 -> 8653.6969
D35: Reis- en verblijfkosten raad | J35: 17077 | K35: =K92 -> 17522 | L35: =L92 -> 17890 | M35: =M92 -> 18301 | N35: =N92 -> 18721 | O35: =O92 -> 19152
D36: =G94 -> Communicatieplan gemeenteraad | J36: 4085 | K36: =K97 -> 4191 | L36: =L97 -> 4279 | M36: =M97 -> 4377 | N36: =N97 -> 4478 | O36: =O97 -> 4581
D37: Werkbudget griffie | J37: 22939 | K37: =K103 -> 23922 | L37: =L103 -> 24508 | M37: =M103 -> 25164 | N37: =N103 -> 25835 | O37: =O103 -> 26521
D38: =G105 -> Rekenkamerfunctie | J38: 41778 | K38: =K108 -> 43712 | L38: =L108 -> 45231 | M38: =M108 -> 47118 | N38: =N108 -> 48879.5 | O38: =O108 -> 49890.8
D39: Gemeentefinanciën | J39: 69833 | K39: =K113 -> 70000 | L39: =L113 -> 71470 | M39: =M113 -> 73114 | N39: =N113 -> 74796 | O39: =O113 -> 76516
D40: =G120 -> Directe toerekening raad | J40: 0 | K40: =K123 -> 0 | L40: =L123 -> 0 | M40: =M123 -> 0 | N40: =N123 -> 0 | O40: =O123 -> 0
D41: Jeugdraad | J41: 1684.892 | K41: =+K118 -> 1728.6992 | L41: =+L118 -> 1765.0019 | M41: =+M118 -> 1805.5969 | N41: =+N118 -> 1847.1256 | O41: =+O118 -> 1889.6095
D42: =G125 -> Gewezen burgemeester | J42: 88189 | K42: =K128 -> 117492 | L42: =L128 -> 119842 | M42: =M128 -> 50933 | N42: =N128 -> 0 | O42: =O128 -> 0
D43: =G130 -> Gewezen college | J43: 171730 | K43: =K133 -> 178593 | L43: =L133 -> 189339 | M43: =M133 -> 195577 | N43: =N133 -> 199488 | O43: =O133 -> 0
D44: =G135 -> College van B&W | J44: 48471 | K44: =K141 -> 18740 | L44: =L141 -> 19134 | M44: =M141 -> 19573 | N44: =N141 -> 20023 | O44: =O141 -> 20485
D45: =G148 -> Directe toerekening college | J45: 0 | K45: =K151 -> 0 | L45: =L151 -> 0 | M45: =M151 -> 0 | N45: =N151 -> 0 | O45: =O151 -> 0
D46: broodjes, bloemen ed | J46: 23541 | K46: =+K146 -> 24153 | L46: =+L146 -> 24660 | M46: =+M146 -> 25227 | N46: =+N146 -> 25807 | O46: =+O146 -> 26401
D47: =G153 -> Representatie | J47: 34813 | K47: =K157 -> 35717 | L47: =L157 -> 36468 | M47: =M157 -> 37307 | N47: =N157 -> 38166 | O47: =O157 -> 39046
D48: Metropoolregio Eindhoven | J48: 306624 | K48: =K172 -> 321495 | L48: =L172 -> 339457 | M48: =M172 -> 354094 | N48: =N172 -> 372394.66 | O48: =O172 -> 385904.18
D49: Actieplan Regio Eindhoven | J49: 78557 | K49: =K177 -> 79636 | L49: =L177 -> 84274 | M49: =M177 -> 87272.28 | N49: =N177 -> 92279.142 | O49: =O177 -> 95696.888
D50: Regionale projecten | J50: 29281 | K50: =K182 -> 29867 | L50: =L182 -> 31121 | M50: =M182 -> 32272 | N50: =N182 -> 33466 | O50: =O182 -> 34704
D51: Convenant SGE | J51: 26628 | K51: =K188 -> 27321 | L51: =L188 -> 27895 | M51: =M188 -> 28537 | N51: =N188 -> 29193 | O51: =O188 -> 29864
D52: Project voorzieningen SGE | J52: 0 | K52: =K193 -> 0 | L52: =L193 -> 0 | M52: =M193 -> 0 | N52: =N193 -> 0 | O52: =O193 -> 0
D53: Challenge ontsluiting | J53: 0 | K53: =K198 -> 0 | L53: =L198 -> 0 | M53: =M198 -> 0 | N53: =N198 -> 0 | O53: =O198 -> 0
D54: Samenwerking Best-Oirschot | J54: 305000 | K54: =+K203 -> 688130 | L54: =+L203 -> 5238 | M54: =+M203 -> 5358 | N54: =+N203 -> 5481 | O54: =+O203 -> 5607
D55: Directe toerekening bestuur | J55: 1433816 | K55: =K209 -> 1508457.5 | L55: =L209 -> 1571604 | M55: =M209 -> 1629568 | N55: =N209 -> 1689677 | O55: =O209 -> 1747010
D56: Directe toerekening regionale samenwerking | J56: 165249.64 | K56: =K215 -> 792976.63 | L56: =L215 -> 800242 | M56: =M215 -> 686911 | N56: =N215 -> 693827 | O56: =O215 -> 700999
D59: Totaal lasten | J59: 2974500.7 | K59: =SUM(K33:K58) -> 4096256.6 | L59: =SUM(L33:L58) -> 3519006 | M59: =SUM(M33:M58) -> 3429319.8 | N59: =SUM(N33:N58) -> 3483441.6 | O59: =SUM(O33:O58) -> 3375675.2
D62: Baten in € (-) | J62: 2025 | K62: 2026 | L62: =+L32 -> 2027 | M62: =+M32 -> 2028 | N62: =+N32 -> 2029 | O62: =+O32 -> 2030
D64: =G159 -> Gewezen bestuurders | J64: -88189 | K64: =K162 -> -117492 | L64: =L162 -> -119842 | M64: =M162 -> -50933 | N64: =N162 -> 0 | O64: =O162 -> 0
D65: =G164 -> Gewezen bestuurders | J65: -171730 | K65: =K167 -> -178593 | L65: =L167 -> -189339 | M65: =M167 -> -195577 | N65: =N167 -> -199488 | O65: =O167 -> 0
D68: Totaal baten | J68: -259919 | K68: =SUM(K64:K67) -> -296085 | L68: =SUM(L64:L67) -> -309181 | M68: =SUM(M64:M67) -> -246510 | N68: =SUM(N64:N67) -> -199488 | O68: =SUM(O64:O67) -> 0
