Workbook

Sheet Uitleg
B1: Wagenparkbeheer – uitleg
B3: Tabbladen
B4: In gebruik – alle voertuigen in gebruik, op volgorde van V-nummer, met kenmerken. Hier wordt gemuteerd (voertuigbeheerder).
B5: Afgestoten – archief van oude voertuigen met jaar van afstoting.
B6: Vervangingsplanning – per V-nummer het eerstvolgende vervangingsjaar, de investeringen per jaar en de afschrijvingslasten (financieel adviseur).
B7: Samenvatting – totalen per jaar: investeringen, afschrijvingslasten, indicatie lease (budgethouder).
B8: Parameters – standaardbedragen en termijnen. Eén keer aanpassen, alles rekent mee.
B9: Controlepunten – onduidelijkheden uit het oude overzicht die nog moeten worden uitgezocht.
B11: Kleuren
B12: Blauw = invoer · Zwart = berekening · Groen = overgenomen van ander tabblad · Geel = parameter of nog in te vullen.
B14: Spelregels lease-koop (personenvoertuigen)
B15: Vervangingsjaar = aanschafjaar + 8. In dat jaar: aanbetaling € 10.000 + belettering € 5.000 + opbouw € 7.000.
... B31: Planning en samenvatting tonen 8 jaar vanaf het eerste planjaar. De planning rekent de eerste 80 regels van 'In gebruik' door.

Sheet In gebruik
A1: Voertuigen in gebruik
A2: Eén regel per V-nummer, op volgorde van V-nummer. Blauw = invoer. Nieuw V-nummer: typ direct onder de tabel, de tabel groeit vanzelf mee. Bij vervanging: oude regel eerst kopiëren naar 'Afgestoten'.
A3: Kolom R t/m T alleen voor lopende lease-koop. Kolom U t/m W sturen de vervangingsplanning.
A4: V-nummer | B4: Kenteken | C4: Merk | D4: Model | E4: Aanschafwijze huidig | F4: Brandstof | G4: Onderdeel | H4: Soort voertuig | I4: Berijder | J4: Aanschafjaar (bouwjaar) | K4: Levensduur (jaar) | L4: Totaal investering huidig | M4: Activakaart | N4: Kredietnummer | O4: Exploitatienummer | P4: Leasesom 1 jaar huidig | Q4: Chassisnummer | R4: Aanbetaling huidig (lease-koop) | S4: Slottermijn huidig (lease-koop) | T4: Jaar slottermijn huidig | U4: Regime volgende vervanging | V4: Raming koopprijs volgende (koop) | W4: Vervangingsjaar handmatig (optioneel) | X4: Toelichting (uit bronbestand) | Y4: Controle-opmerking
A5: V01 | B5: 26-BXG-9 | C5: Scania | D5: P320 | E5: Koop | F5: Diesel | G5: Vrachtwagen | H5: Vrachtwagen | I5: Herman v Beerendonk | J5: 2024 | K5: 8 | L5: 248960 | M5: 119 | N5: 7205037 | Q5: YS2P6X20005696172 | U5: Koop | V5: 248960 | X5: Standaard aanbesteding / koop bij volgende aanschaf.
A6: V02 | B6: 06-BVN-2 | C6: DAF | D6: M4EN3 | E6: Koop | F6: Diesel | G6: Rioolvoertuig | H6: Rioolvoertuig | I6: Lau/William | J6: 2023 | K6: 12 | L6: 358180 | M6: 625 | N6: 7205034 | Q6: XLRAEM4100G432765 | U6: Koop | V6: 358180 | X6: Standaard aanbesteding / koop bij volgende aanschaf.
A7: V03 | B7: BZ-TZ-45 | C7: MAN | D7: TGM 18.250 4X4 BB EEV | E7: Koop | F7: Diesel | G7: Vrachtwagen | H7: Vrachtwagen | I7: STROOIEN | J7: 2012 | Q7: WMAN38ZZ4CY278745 | U7: Doorschuiven | W7: 2032 | X7: V1 wordt doorgeschoven naar V3 in 2032. Dit voertuig wordt na einde afschrijving V1 vervangen door V1. Het oude V3 voertuig wordt dan afgestoten. | Y7: Geen eigen vervanging: V01 schuift in 2032 door naar V03, oude V03 wordt afgestoten. Afschrijftermijn ontbreekt.
A8: V04 | B8: V-88-FPL | C8: Volkswagen | D8: Crafter (Open Laadbak) | E8: Koop | F8: Diesel | G8: Stratenmakers | H8: bedrijfsauto | I8: Marnick/Henry | J8: 2024 | K8: 8 | L8: 72896 | M8: 632 | N8: 7205035 | Q8: WV3ZZZSZ2R9032595 | U8: Lease-koop | X8: Volgend voertuig wordt aangeschaft obv een lease-koopconstructie.
A9: V05 | B9: H-872-GK | C9: Hyundai | D9: Kona | E9: Koop | F9: Elektrisch | G9: Kantoor | H9: personenauto | I9: Jos / Martin | J9: 2021 | K9: 8 | L9: 65000 | N9: 7205053 | Q9: KMHK281HFKU031442 | U9: Lease-koop | X9: Begroting 2027: opgevoerd als koop in 2029 | Y9: Begroting 2027 rekent met KOOP in 2029 (€ 65.000). Hier volgens nieuwe regel lease-koop. Keuze bevestigen.
A10: V06 | B10: V-70-NRS | C10: Ford | D10: Transit E | E10: Lease-koop | F10: Elektrisch | G10: Cultuur / Bossen | H10: bedrijfsauto | I10: Jilles Eikelenboom | J10: 2026 | K10: 8 | L10: 44420 | N10: 7205045 | O10: 635901 | P10: 11786.52 | Q10: ZFA26300006128328 | R10: 11000 | S10: 30000 | T10: =IF(S10>0,J10+p_SlotJr,"") -> 2028 | U10: Lease-koop | X10: Aanbetaling is € 11.000 excl btw, slotbetaling is € 30.000. Begroting 2027, slotbetaling verwerkt | Y10: Chassisnummer gelijk aan afgestoten V98. Controleren.
A11: V07 | B11: VG-092-L | C11: Fiat | D11: Ducato | E11: Koop | F11: Diesel | G11: Algemene dienst | H11: bedrijfsauto | I11: Nicolai v/d Heijden | J11: 2013 | K11: 8 | L11: 65000 | M11: 803 | N11: 7205051 | Q11: ZFA25000002508469 | U11: Koop | V11: 65000 | W11: 2027 | X11: Begroting 2027: opgevoerd als koop in 2027 | Y11: Theoretisch vervangen in 2021; begroot als koop in 2027.
A12: V08 | B12: V-72-NRS | C12: Ford | D12: Transit E | E12: Lease-koop | F12: Elektrisch | G12: Stratenmakers | H12: personenauto | I12: Jordy / Robbie | J12: 2026 | K12: 8 | L12: 44420 | M12: 648 | N12: 7205048 | O12: 617901 | P12: 11786.52 | Q12: VF3GJ9HXC95290270 | R12: 11000 | S12: 30000 | T12: =IF(S12>0,J12+p_SlotJr,"") -> 2028 | U12: Lease-koop | X12: Aanbetaling is € 11.000 excl btw, slotbetaling is € 30.000.Begroting 2027 slotbetaling verwerkt | Y12: Soort 'personenauto' lijkt onjuist (Ford Transit = bedrijfsauto). Chassisnummer gelijk aan afgestoten V93.
A13: V09 | B13: Z-684-FB | C13: Volvo | D13: EX30 | E13: Koop | F13: Elektrisch | G13: Kantoor | H13: personenauto | I13: Marco | J13: 2024 | K13: 8 | L13: 38664 | M13: 472 | N13: 7205039 | U13: Lease-koop | X13: Volgend voertuig wordt aangeschaft obv een lease-koopconstructie. | Y13: Chassisnummer ontbreekt.
A14: V10 | B14: V-96-LPT | C14: Renault | D14: Kangoo Electrisch | E14: Koop | F14: Elektrisch | G14: Storingsdienst | H14: bedrijfsauto | I14: Storingsdienst | J14: 2025 | K14: 8 | L14: 30093 | M14: 461 | N14: 7205043 | Q14: ZFA26300006K81863 | U14: Lease-koop | X14: Volgend voertuig wordt aangeschaft obv een lease-koopconstructie. | Y14: Chassisnummer gelijk aan V14. Controleren.
A15: V11 | C15: Ford | D15: Ranger | E15: Lease-koop | F15: Hybride | G15: Cultuur / Bossen | H15: bedrijfsauto | I15: Antoon Kemps | J15: 2026 | K15: 8 | L15: 46500 | N15: 7205046 | O15: 635901 | P15: 13448.529 | R15: 11000 | S15: 35500 | T15: =IF(S15>0,J15+p_SlotJr,"") -> 2028 | U15: Lease-koop | X15: Aanbetaling is € 11.000 excl btw, slotbetaling is € 35.500, Begroting 2027 slotbetaling verwerkt. | Y15: Kenteken en chassisnummer ontbreken.
A16: V12 | B16: V-05-JGK | C16: Mercedes | D16: E-sprinter | E16: Koop | F16: Elektrisch | G16: Groen | H16: bedrijfsauto | I16: Addry v Oorschot | J16: 2024 | K16: 8 | L16: 65770 | M16: 465 | N16: 7205044 | Q16: W1V3UBFZ5SP767543 | U16: Lease-koop | X16: Volgend voertuig wordt aangeschaft obv een lease-koopconstructie.
A17: V13 | B17: V-708-FT | C17: Fiat | D17: Ducato | E17: Koop | F17: Diesel | G17: Algemene dienst | H17: bedrijfsauto | I17: Wil van Dal | J17: 2017 | K17: 8 | L17: 65000 | M17: 520 | N17: 7205052 | Q17: ZFA25000002D82946 | U17: Koop | V17: 65000 | W17: 2027 | X17: Begroting: opgevoerd als koop in 2027 | Y17: Theoretisch vervangen in 2025; begroot als koop in 2027.
A18: V14 | B18: V-603-LV | C18: Fiat | D18: Doblo | E18: Koop | F18: Diesel | G18: Speelt/groen | H18: bedrijfsauto | I18: Ruud Liebrechts | J18: 2018 | K18: 8 | L18: 45000 | N18: 7205058 | Q18: ZFA26300006K81863 | U18: Lease-koop | W18: 2027 | X18: Volgend voertuig wordt aangeschaft obv een lease-koopconstructie. | Y18: Bron zegt 'werkelijk vervangen in 2026', maar staat nog in gebruik. Chassisnummer gelijk aan V10.
A19: V15 | C19: Ford | D19: Transit Custom | E19: Lease-koop | F19: Hybride | G19: Garage | H19: bedrijfsauto | I19: Pascal Jonkman | J19: 2026 | K19: 8 | L19: 41000 | M19: 463 | N19: 7205033 | O19: 604901 | P19: 11641.686 | R19: 11000 | S19: 30000 | T19: =IF(S19>0,J19+p_SlotJr,"") -> 2028 | U19: Lease-koop | X19: Aanbetaling is € 11.000 excl btw, slotbetaling is € 30.000. Begroting 2027: slotbetaling verwerkt | Y19: Kenteken en chassisnummer ontbreken.
A20: V16 | C20: Ford | D20: Transit Custom | E20: Lease-koop | F20: Hybride | G20: Sport | H20: bedrijfsauto | I20: Mark Oerlemans | J20: 2026 | K20: 8 | L20: 49610 | M20: 776 | N20: 7205032 | O20: 630901 | P20: 14085.84 | R20: 13310 | S20: 36300 | T20: =IF(S20>0,J20+p_SlotJr,"") -> 2028 | U20: Lease-koop | X20: Aanbetaling is € 13.310 incl btw, slotbetaling is € 36.300. Begroting 2027 slotbetaling verwerkt | Y20: Aanbetaling en slottermijn zijn INCL. btw; de rest is excl. btw.
A21: V17 | B21: V-73-NRS | C21: Ford | D21: Transit E | E21: Lease-koop | F21: Elektrisch | G21: Timmerman | H21: bedrijfsauto | I21: Arie v Dijk | J21: 2026 | K21: 8 | L21: 44420 | M21: 647 | N21: 7205047 | O21: 604901 | P21: 11786.52 | Q21: ZFA26300006128325 | R21: 11000 | S21: 30000 | T21: =IF(S21>0,J21+p_SlotJr,"") -> 2028 | U21: Lease-koop | X21: Aanbetaling is € 11.000 excl btw, slotbetaling is € 30.000. Begroting 2027: slotbetaling verwerkt | Y21: Chassisnummer gelijk aan afgestoten V97. Controleren.
A22: V18 | B22: T-63-FGV | C22: Fendt | D22: 209S | E22: Koop | F22: Diesel | G22: Sport | H22: tractor | I22: x | J22: 2023 | K22: 15 | L22: 121968 | M22: 458 | N22: 7205027 | Q22: E26162 | U22: Koop | V22: 121968 | X22: Standaard aanbesteding / koop bij volgende aanschaf.
A23: V19 | B23: TBK-67-P | C23: New Holland | D23: BOOMER 3050 DB (DBCCSC) | E23: Koop | F23: Diesel | G23: Sport | H23: tractor | I23: Divers | J23: 2012 | K23: 15 | L23: 80000 | M23: 823 | N23: 7205057 | Q23: ZBDB19065 | U23: Koop | V23: 80000 | X23: Standaard aanbesteding / koop bij volgende aanschaf.
A24: V20 | B24: TDT-42-X | C24: Kubota | E24: Koop | F24: Diesel | G24: Cultuur / Bossen | H24: tractor | I24: Divers | J24: 2009 | K24: 20 | L24: 100000 | Q24: 80450 | U24: Koop | V24: 100000 | X24: Standaard aanbesteding / koop bij volgende aanschaf. | Y24: Model en kredietnummer ontbreken.
A25: V21 | B25: T-80-GGN | C25: New Holland | D25: BOOMER NH 55CAB (DBCCSC) | E25: Koop | F25: Diesel | G25: Sport | H25: tractor | I25: Divers | J25: 2024 | K25: 10 | L25: 51100 | M25: 518 | N25: 7205041 | U25: Koop | V25: 51100 | X25: Standaard aanbesteding / koop bij volgende aanschaf. | Y25: Chassisnummer ontbreekt.
A26: V24 | B26: geen kenteken | C26: EP | D26: Heftruck LI-ION 15 Electrisch CPD15TVL | E26: Koop | F26: Elektrisch | G26: Werf | H26: vorkheftruck | I26: Divers | J26: 2023 | K26: 10 | L26: 19000 | Q26: 2311900679 | U26: Koop | V26: 19000 | X26: Standaard aanbesteding / koop bij volgende aanschaf.
A27: V25 | B27: geen kenteken | C27: Heli | D27: Diesel Heftruck | E27: Koop | F27: Diesel | G27: Werf | H27: vorkheftruck | I27: Divers | J27: 2007 | K27: 8 | L27: 50000 | N27: 7205056 | Q27: 01030A6594 | U27: Koop | V27: 50000 | W27: 2028 | X27: Standaard aanbesteding / koop bij volgende aanschaf. | Y27: Aanschaf 2007; vervanging uitgesteld naar 2028.
A28: V26 | B28: RG-730-S | C28: Renault | D28: Zoe Gemeentehuis | E28: Koop | F28: Elektrisch | G28: Algemeen | H28: personenauto | I28: Dienstauto | J28: 2017 | K28: 8 | L28: 45000 | N28: 7205054 | Q28: VF3GJKFWC95250147 | U28: Koop | V28: 45000 | W28: 2027 | X28: Begroting 2027 verwerkt als koop. Volgend voertuig wordt aangeschaft obv een lease-koopconstructie. | Y28: Begroting 2027: koop in 2027. Vervanging daarna via lease-koop.
A29: V27 | B29: PX-814-X | C29: Renault | D29: Zoe Gemeentehuis | E29: Koop | F29: Elektrisch | G29: Handhaving | H29: personenauto | I29: Dienstauto | J29: 2017 | K29: 8 | L29: 45000 | N29: 7205055 | Q29: VF1AGVYF058298996 | U29: Koop | V29: 45000 | W29: 2027 | X29: Begroting 2027 verwerkt als koop. Volgend voertuig wordt aangeschaft obv een lease-koopconstructie. | Y29: Begroting 2027: koop in 2027. Vervanging daarna via lease-koop.
A30: V28 | B30: KGN-02-Z | C30: Opel | D30: Mokka ev 115kw | E30: Lease-koop | F30: Elektrisch | G30: Veiligheid | H30: personenauto | I30: BOA | J30: 2026 | K30: 8 | L30: 30000 | T30: =IF(S30>0,J30+p_SlotJr,"") | U30: Lease-koop | X30: Slotbetaling verwerkt in begroting 2027 | Y30: Aanbetaling en slottermijn onbekend: invullen in kolom R en S.
A31: V29 | B31: X-385-DH | C31: Volkswagen | D31: ID3 | E31: Koop | F31: Elektrisch | G31: Handhaving | H31: personenauto | I31: Dienstauto | J31: 2023 | K31: 8 | L31: 41530 | M31: 631 | N31: 7205036 | Q31: WVWZZZE19RP001638 | U31: Lease-koop | X31: Volgend voertuig wordt aangeschaft obv een lease-koopconstructie.

Sheet Afgestoten
A1: Afgestoten voertuigen
A2: Archief. Bij vervanging: kopieer de regel uit 'In gebruik' naar onder deze tabel en vul het jaar van afstoting in.
A4: V-nummer | B4: Kenteken | C4: Merk | D4: Model | E4: Aanschafwijze | F4: Brandstof | G4: Onderdeel | H4: Soort voertuig | I4: Berijder | J4: Aanschafjaar (bouwjaar) | K4: Levensduur (jaar) | L4: Totaal investering | M4: Activakaart | N4: Kredietnummer | O4: Chassisnummer | P4: Jaar afstoting | Q4: Opmerking
A5: V11 | B5: VH-073-L | C5: Volkswagen | D5: Amarok | E5: Koop | F5: Diesel | G5: Cultuur / Bossen | H5: bedrijfsauto | I5: Antoon Kemps | J5: 2014 | K5: 8 | O5: WV1ZZZ2HZEH012489 | P5: 2026 | Q5: Opgevolgd door huidige V11.
A6: V15 | B6: V-138-DP | C6: Renault | D6: Trafic | E6: Koop | F6: Diesel | G6: Garage | H6: bedrijfsauto | I6: Pascal Jonkman | J6: 2018 | K6: 8 | O6: VF1FL000356745538 | P6: 2026 | Q6: Opgevolgd door huidige V15.
A7: V16 | B7: VG-093-L | C7: Fiat | D7: Ducato | E7: Koop | F7: Diesel | G7: Sport | H7: bedrijfsauto | I7: Mark Oerlemans | J7: 2013 | K7: 8 | O7: ZFA25000002508608 | P7: 2026 | Q7: Opgevolgd door huidige V16.
A8: V28 | B8: PR-058-F | C8: Opel | D8: Mokka X | E8: Koop | F8: Benzine | G8: Veiligheid | H8: personenauto | I8: BOA | J8: 2017 | K8: 8 | L8: 80000 | N8: 7205049 | O8: W0LJC7E89HB204443 | P8: 2026 | Q8: Opgevolgd door huidige V28.
A9: V93 | B9: 58-XN-GS | C9: Peugeot | D9: Partner | F9: Diesel | G9: Stratenmakers | H9: personenauto | I9: Jordy / Robbie | J9: 2007 | K9: 8 | L9: 65000 | O9: VF3GJ9HXC95290270 | P9: 2026 | Q9: Chassisnummer stond in kolom toelichting. Zelfde chassisnummer als huidige V08: controleren.
A10: V94 | B10: 05-SZ-NF | C10: Peugeot | D10: Partner | F10: Diesel | G10: Tijdelijk kantoor | H10: personenauto | I10: John Beerens | J10: 2006 | K10: 8 | L10: 43000 | M10: 6971005/434335/M05SZNF | O10: VF3GJ9HWC95219947 | Q10: Jaar afstoting onbekend (bron: x). Aanvullen.
A11: V95 | B11: TFN-07-R | C11: Matec Terberg | D11: City Cat 5006 XL | F11: Diesel | G11: Veegwagen | H11: veegwagen | I11: William vd Boomen | J11: 2015 | K11: 8 | L11: 240000 | M11: 6210601/434335 | O11: TEBC50AF3FKSN7123 | Q11: Jaar afstoting onbekend (bron: x). Aanvullen.
A12: V96 | B12: VG-683-L | C12: Fiat | D12: Doblo | F12: Aardgas | G12: Speelwerktuigen | H12: bedrijfsauto | I12: Ruud Liebregts | J12: 2013 | K12: 8 | L12: 65000 | O12: ZFA26300006128330 | P12: 2027 | Q12: Afstoting 2027 ligt in de toekomst: is dit al gebeurd? Chassis gelijk aan geen huidig voertuig.
A13: V97 | B13: VG-082-L | C13: Fiat | D13: Doblo | F13: Aardgas | G13: Timmerman | H13: bedrijfsauto | I13: Arie v Dijk | J13: 2013 | K13: 8 | L13: 65000 | O13: ZFA26300006128325 | P13: 2025 | Q13: Zelfde chassisnummer als huidige V17: controleren.
A14: V98 | B14: VG-083-L | C14: Fiat | D14: Doblo | F14: Aardgas | G14: Cultuur / Bossen | H14: bedrijfsauto | I14: x | J14: 2013 | K14: 8 | L14: 65000 | O14: ZFA26300006128328 | P14: 2027 | Q14: Afstoting 2027 ligt in de toekomst: is dit al gebeurd? Zelfde chassisnummer als huidige V06.
A15: V99 | B15: VG-094-L | C15: Fiat | D15: Ducato (open laadbak) | F15: Diesel | G15: TIJDELIJK alg dienst | H15: bedrijfsauto | I15: Willie v Dal | J15: 2013 | K15: 8 | L15: 72000 | M15: 6210102/434335 | O15: ZFA25000002518269 | Q15: Jaar afstoting onbekend (bron: x). Aanvullen.

Sheet Vervangingsplanning
A1: Vervangingsplanning en investeringen
A2: Alles berekend uit 'In gebruik' en 'Parameters' (niets invullen op dit blad). Eén regel per V-nummer, eerstvolgende vervanging.
A3: Lease-koop: aanbetaling + belettering + opbouw in vervangingsjaar, slottermijn in jaar overname, afschrijving 6 jaar vanaf jaar na overname. Koop: koopprijs in vervangingsjaar, afschrijving over levensduur vanaf jaar erna. Status 'Over levensduur' = vervanging had al moeten plaatsvinden.
A4: Doorgerekend: de eerste 80 regels van 'In gebruik'.
A5: Totaal | K5: =SUM(K8:K87) -> 140000 | L5: =SUM(L8:L87) -> 70000 | M5: =SUM(M8:M87) -> 98000 | N5: =SUM(N8:N87) -> 490000 | O5: =SUM(O8:O87) -> 28482 | P5: =SUM(P8:P87) -> 1249208 | Q5: =SUM(Q8:Q87) -> 2047208 | S5: =SUM(S8:S87) -> 253192.87 | U5: =SUM(U8:U87) -> 168000 | V5: =SUM(V8:V87) -> 68310 | W5: =SUM(W8:W87) -> 191800 | AA5: =SUM(AA8:AA87) -> 322000 | AB5: =SUM(AB8:AB87) -> 241800 | AC5: =SUM(AC8:AC87) -> 157000 | AD5: =SUM(AD8:AD87) -> 0 | AE5: =SUM(AE8:AE87) -> 57000 | AF5: =SUM(AF8:AF87) -> 314960 | AG5: =SUM(AG8:AG87) -> 76000 | AH5: =SUM(AH8:AH87) -> 310100 | AJ5: =SUM(AJ8:AJ87) -> 0 | AK5: =SUM(AK8:AK87) -> 32833.333 | AL5: =SUM(AL8:AL87) -> 82435 | AM5: =SUM(AM8:AM87) -> 96935 | AN5: =SUM(AN8:AN87) -> 96935 | AO5: =SUM(AO8:AO87) -> 106435 | AP5: =SUM(AP8:AP87) -> 137555 | AQ5: =SUM(AQ8:AQ87) -> 148955
AA6: Investeringen per jaar (eerstvolgende vervanging + openstaande slottermijnen) | AJ6: Afschrijvingslasten van deze investeringen per jaar
A7: V-nummer | B7: Kenteken | C7: Soort voertuig | D7: Onderdeel | E7: Regime volgende | F7: Aanschafjaar huidig | G7: Levensduur | H7: Einde econ. levensduur | I7: Eerstvolgend vervangingsjaar | J7: Status | K7: Aanbetaling | L7: Belettering | M7: Opbouw | N7: Slottermijn | O7: Jaar overname | P7: Koopprijs | Q7: Totaal investering nieuw | R7: Afschrijftermijn nieuw | S7: Afschrijving per jaar | T7: Start afschrijving | U7: Jaarlease (info) | V7: Aanbetaling huidig | W7: Slottermijn huidig | X7: Jaar slottermijn huidig | Y7: Leasesom huidig (info) | AA7: =p_Start -> 2027 | AB7: =AA7+1 -> 2028 | AC7: =AB7+1 -> 2029 | AD7: =AC7+1 -> 2030 | AE7: =AD7+1 -> 2031 | AF7: =AE7+1 -> 2032 | AG7: =AF7+1 -> 2033 | AH7: =AG7+1 -> 2034 | AJ7: =p_Start -> 2027 | AK7: =AJ7+1 -> 2028 | AL7: =AK7+1 -> 2029 | AM7: =AL7+1 -> 2030 | AN7: =AM7+1 -> 2031 | AO7: =AN7+1 -> 2032 | AP7: =AO7+1 -> 2033 | AQ7: =AP7+1 -> 2034
A8: =IF(INDEX('In gebruik'!$A:$A,ROW()+(-3))="","",INDEX('In gebruik'!$A:$A,ROW()+(-3))) -> V01 | B8: =IF($A8="","",INDEX('In gebruik'!$B:$B,ROW()+(-3))&"") -> 26-BXG-9 | C8: =IF($A8="","",INDEX('In gebruik'!$H:$H,ROW()+(-3))&"") -> Vrachtwagen | D8: =IF($A8="","",INDEX('In gebruik'!$G:$G,ROW()+(-3))&"") -> Vrachtwagen | E8: =IF($A8="","",INDEX('In gebruik'!$U:$U,ROW()+(-3))&"") -> Koop | F8: =IF($A8="",0,N(INDEX('In gebruik'!$J:$J,ROW()+(-3)))) -> 2024 | G8: =IF($A8="",0,N(INDEX('In gebruik'!$K:$K,ROW()+(-3)))) -> 8 | H8: =IF(G8>0,F8+G8-1,0) -> 2031 | I8: =IF($A8="",0,IF(N(INDEX('In gebruik'!$W:$W,ROW()+(-3)))>0,N(INDEX('In gebruik'!$W:$W,ROW()+(-3))),IF(G8>0,MAX(F8+G8,p_Start),0))) -> 2032 | J8: =IF($A8="","",IF(AND(G8>0,F8+G8<p_Start),"Over levensduur",IF(AND(I8>0,I8<=p_Start+3),"In begrotingsperiode",""))) | K8: =IF($E8="Lease-koop",p_Aanbet,0) -> 0 | L8: =IF($E8="Lease-koop",p_Belet,0) -> 0 | M8: =IF($E8="Lease-koop",p_Opbouw,0) -> 0 | N8: =IF($E8="Lease-koop",p_Slot,0) -> 0 | O8: =IF($E8="Lease-koop",I8+p_SlotJr,0) -> 0 | P8: =IF($E8="Koop",N(INDEX('In gebruik'!$V:$V,ROW()+(-3))),0) -> 248960 | Q8: =K8+L8+M8+N8+P8 -> 248960 | R8: =IF($E8="Lease-koop",p_AfschrLK,IF($E8="Koop",G8,0)) -> 8 | S8: =IF(R8>0,Q8/R8,0) -> 31120 | T8: =IF($E8="Lease-koop",O8+1,IF($E8="Koop",I8+1,0)) -> 2033 | U8: =IF($E8="Lease-koop",p_Lease,0) -> 0 | V8: =IF($A8="",0,N(INDEX('In gebruik'!$R:$R,ROW()+(-3)))) -> 0 | W8: =IF($A8="",0,N(INDEX('In gebruik'!$S:$S,ROW()+(-3)))) -> 0 | X8: =IF(W8>0,N(INDEX('In gebruik'!$T:$T,ROW()+(-3))),0) -> 0 | Y8: =IF(W8>0,IF(N(INDEX('In gebruik'!$P:$P,ROW()+(-3)))>0,N(INDEX('In gebruik'!$P:$P,ROW()+(-3))),p_Lease),0) -> 0 | AA8: =IF($Q8+$W8=0,0,IF(AA$7=$I8,$K8+$L8+$M8+$P8,0)+IF(AA$7=$O8,$N8,0)+IF(AA$7=$X8,$W8,0)) -> 0 | AB8: =IF($Q8+$W8=0,0,IF(AB$7=$I8,$K8+$L8+$M8+$P8,0)+IF(AB$7=$O8,$N8,0)+IF(AB$7=$X8,$W8,0)) -> 0 | AC8: =IF($Q8+$W8=0,0,IF(AC$7=$I8,$K8+$L8+$M8+$P8,0)+IF(AC$7=$O8,$N8,0)+IF(AC$7=$X8,$W8,0)) -> 0 | AD8: =IF($Q8+$W8=0,0,IF(AD$7=$I8,$K8+$L8+$M8+$P8,0)+IF(AD$7=$O8,$N8,0)+IF(AD$7=$X8,$W8,0)) -> 0 | AE8: =IF($Q8+$W8=0,0,IF(AE$7=$I8,$K8+$L8+$M8+$P8,0)+IF(AE$7=$O8,$N8,0)+IF(AE$7=$X8,$W8,0)) -> 0 | AF8: =IF($Q8+$W8=0,0,IF(AF$7=$I8,$K8+$L8+$M8+$P8,0)+IF(AF$7=$O8,$N8,0)+IF(AF$7=$X8,$W8,0)) -> 248960 | AG8: =IF($Q8+$W8=0,0,IF(AG$7=$I8,$K8+$L8+$M8+$P8,0)+IF(AG$7=$O8,$N8,0)+IF(AG$7=$X8,$W8,0)) -> 0 | AH8: =IF($Q8+$W8=0,0,IF(AH$7=$I8,$K8+$L8+$M8+$P8,0)+IF(AH$7=$O8,$N8,0)+IF(AH$7=$X8,$W8,0)) -> 0 | AJ8: =IF(AND($S8>0,AJ$7>=$T8,AJ$7<$T8+$R8),$S8,0)+IF(AND($W8>0,AJ$7>$X8,AJ$7<=$X8+p_AfschrLK),($V8+$W8)/p_AfschrLK,0) -> 0 | AK8: =IF(AND($S8>0,AK$7>=$T8,AK$7<$T8+$R8),$S8,0)+IF(AND($W8>0,AK$7>$X8,AK$7<=$X8+p_AfschrLK),($V8+$W8)/p_AfschrLK,0) -> 0 | AL8: =IF(AND($S8>0,AL$7>=$T8,AL$7<$T8+$R8),$S8,0)+IF(AND($W8>0,AL$7>$X8,AL$7<=$X8+p_AfschrLK),($V8+$W8)/p_AfschrLK,0) -> 0 | AM8: =IF(AND($S8>0,AM$7>=$T8,AM$7<$T8+$R8),$S8,0)+IF(AND($W8>0,AM$7>$X8,AM$7<=$X8+p_AfschrLK),($V8+$W8)/p_AfschrLK,0) -> 0 | AN8: =IF(AND($S8>0,AN$7>=$T8,AN$7<$T8+$R8),$S8,0)+IF(AND($W8>0,AN$7>$X8,AN$7<=$X8+p_AfschrLK),($V8+$W8)/p_AfschrLK,0) -> 0 | AO8: =IF(AND($S8>0,AO$7>=$T8,AO$7<$T8+$R8),$S8,0)+IF(AND($W8>0,AO$7>$X8,AO$7<=$X8+p_AfschrLK),($V8+$W8)/p_AfschrLK,0) -> 0 | AP8: =IF(AND($S8>0,AP$7>=$T8,AP$7<$T8+$R8),$S8,0)+IF(AND($W8>0,AP$7>$X8,AP$7<=$X8+p_AfschrLK),($V8+$W8)/p_AfschrLK,0) -> 31120 | AQ8: =IF(AND($S8>0,AQ$7>=$T8,AQ$7<$T8+$R8),$S8,0)+IF(AND($W8>0,AQ$7>$X8,AQ$7<=$X8+p_AfschrLK),($V8+$W8)/p_AfschrLK,0) -> 31120
A9: =IF(INDEX('In gebruik'!$A:$A,ROW()+(-3))="","",INDEX('In gebruik'!$A:$A,ROW()+(-3))) -> V02 | B9: =IF($A9="","",INDEX('In gebruik'!$B:$B,ROW()+(-3))&"") -> 06-BVN-2 | C9: =IF($A9="","",INDEX('In gebruik'!$H:$H,ROW()+(-3))&"") -> Rioolvoertuig | D9: =IF($A9="","",INDEX('In gebruik'!$G:$G,ROW()+(-3))&"") -> Rioolvoertuig | E9: =IF($A9="","",INDEX('In gebruik'!$U:$U,ROW()+(-3))&"") -> Koop | F9: =IF($A9="",0,N(INDEX('In gebruik'!$J:$J,ROW()+(-3)))) -> 2023 | G9: =IF($A9="",0,N(INDEX('In gebruik'!$K:$K,ROW()+(-3)))) -> 12 | H9: =IF(G9>0,F9+G9-1,0) -> 2034 | I9: =IF($A9="",0,IF(N(INDEX('In gebruik'!$W:$W,ROW()+(-3)))>0,N(INDEX('In gebruik'!$W:$W,ROW()+(-3))),IF(G9>0,MAX(F9+G9,p_Start),0))) -> 2035 | J9: =IF($A9="","",IF(AND(G9>0,F9+G9<p_Start),"Over levensduur",IF(AND(I9>0,I9<=p_Start+3),"In begrotingsperiode",""))) | K9: =IF($E9="Lease-koop",p_Aanbet,0) -> 0 | L9: =IF($E9="Lease-koop",p_Belet,0) -> 0 | M9: =IF($E9="Lease-koop",p_Opbouw,0) -> 0 | N9: =IF($E9="Lease-koop",p_Slot,0) -> 0 | O9: =IF($E9="Lease-koop",I9+p_SlotJr,0) -> 0 | P9: =IF($E9="Koop",N(INDEX('In gebruik'!$V:$V,ROW()+(-3))),0) -> 358180 | Q9: =K9+L9+M9+N9+P9 -> 358180 | R9: =IF($E9="Lease-koop",p_AfschrLK,IF($E9="Koop",G9,0)) -> 12 | S9: =IF(R9>0,Q9/R9,0) -> 29848.333 | T9: =IF($E9="Lease-koop",O9+1,IF($E9="Koop",I9+1,0)) -> 2036 | U9: =IF($E9="Lease-koop",p_Lease,0) -> 0 | V9: =IF($A9="",0,N(INDEX('In gebruik'!$R:$R,ROW()+(-3)))) -> 0 | W9: =IF($A9="",0,N(INDEX('In gebruik'!$S:$S,ROW()+(-3)))) -> 0 | X9: =IF(W9>0,N(INDEX('In gebruik'!$T:$T,ROW()+(-3))),0) -> 0 | Y9: =IF(W9>0,IF(N(INDEX('In gebruik'!$P:$P,ROW()+(-3)))>0,N(INDEX('In gebruik'!$P:$P,ROW()+(-3))),p_Lease),0) -> 0 | AA9: =IF($Q9+$W9=0,0,IF(AA$7=$I9,$K9+$L9+$M9+$P9,0)+IF(AA$7=$O9,$N9,0)+IF(AA$7=$X9,$W9,0)) -> 0 | AB9: =IF($Q9+$W9=0,0,IF(AB$7=$I9,$K9+$L9+$M9+$P9,0)+IF(AB$7=$O9,$N9,0)+IF(AB$7=$X9,$W9,0)) -> 0 | AC9: =IF($Q9+$W9=0,0,IF(AC$7=$I9,$K9+$L9+$M9+$P9,0)+IF(AC$7=$O9,$N9,0)+IF(AC$7=$X9,$W9,0)) -> 0 | AD9: =IF($Q9+$W9=0,0,IF(AD$7=$I9,$K9+$L9+$M9+$P9,0)+IF(AD$7=$O9,$N9,0)+IF(AD$7=$X9,$W9,0)) -> 0 | AE9: =IF($Q9+$W9=0,0,IF(AE$7=$I9,$K9+$L9+$M9+$P9,0)+IF(AE$7=$O9,$N9,0)+IF(AE$7=$X9,$W9,0)) -> 0 | AF9: =IF($Q9+$W9=0,0,IF(AF$7=$I9,$K9+$L9+$M9+$P9,0)+IF(AF$7=$O9,$N9,0)+IF(AF$7=$X9,$W9,0)) -> 0 | AG9: =IF($Q9+$W9=0,0,IF(AG$7=$I9,$K9+$L9+$M9+$P9,0)+IF(AG$7=$O9,$N9,0)+IF(AG$7=$X9,$W9,0)) -> 0 | AH9: =IF($Q9+$W9=0,0,IF(AH$7=$I9,$K9+$L9+$M9+$P9,0)+IF(AH$7=$O9,$N9,0)+IF(AH$7=$X9,$W9,0)) -> 0 | AJ9: =IF(AND($S9>0,AJ$7>=$T9,AJ$7<$T9+$R9),$S9,0)+IF(AND($W9>0,AJ$7>$X9,AJ$7<=$X9+p_AfschrLK),($V9+$W9)/p_AfschrLK,0) -> 0 | AK9: =IF(AND($S9>0,AK$7>=$T9,AK$7<$T9+$R9),$S9,0)+IF(AND($W9>0,AK$7>$X9,AK$7<=$X9+p_AfschrLK),($V9+$W9)/p_AfschrLK,0) -> 0 | AL9: =IF(AND($S9>0,AL$7>=$T9,AL$7<$T9+$R9),$S9,0)+IF(AND($W9>0,AL$7>$X9,AL$7<=$X9+p_AfschrLK),($V9+$W9)/p_AfschrLK,0) -> 0 | AM9: =IF(AND($S9>0,AM$7>=$T9,AM$7<$T9+$R9),$S9,0)+IF(AND($W9>0,AM$7>$X9,AM$7<=$X9+p_AfschrLK),($V9+$W9)/p_AfschrLK,0) -> 0 | AN9: =IF(AND($S9>0,AN$7>=$T9,AN$7<$T9+$R9),$S9,0)+IF(AND($W9>0,AN$7>$X9,AN$7<=$X9+p_AfschrLK),($V9+$W9)/p_AfschrLK,0) -> 0 | AO9: =IF(AND($S9>0,AO$7>=$T9,AO$7<$T9+$R9),$S9,0)+IF(AND($W9>0,AO$7>$X9,AO$7<=$X9+p_AfschrLK),($V9+$W9)/p_AfschrLK,0) -> 0 | AP9: =IF(AND($S9>0,AP$7>=$T9,AP$7<$T9+$R9),$S9,0)+IF(AND($W9>0,AP$7>$X9,AP$7<=$X9+p_AfschrLK),($V9+$W9)/p_AfschrLK,0) -> 0 | AQ9: =IF(AND($S9>0,AQ$7>=$T9,AQ$7<$T9+$R9),$S9,0)+IF(AND($W9>0,AQ$7>$X9,AQ$7<=$X9+p_AfschrLK),($V9+$W9)/p_AfschrLK,0) -> 0
A10: =IF(INDEX('In gebruik'!$A:$A,ROW()+(-3))="","",INDEX('In gebruik'!$A:$A,ROW()+(-3))) -> V03 | B10: =IF($A10="","",INDEX('In gebruik'!$B:$B,ROW()+(-3))&"") -> BZ-TZ-45 | C10: =IF($A10="","",INDEX('In gebruik'!$H:$H,ROW()+(-3))&"") -> Vrachtwagen | D10: =IF($A10="","",INDEX('In gebruik'!$G:$G,ROW()+(-3))&"") -> Vrachtwagen | E10: =IF($A10="","",INDEX('In gebruik'!$U:$U,ROW()+(-3))&"") -> Doorschuiven | F10: =IF($A10="",0,N(INDEX('In gebruik'!$J:$J,ROW()+(-3)))) -> 2012 | G10: =IF($A10="",0,N(INDEX('In gebruik'!$K:$K,ROW()+(-3)))) -> 0 | H10: =IF(G10>0,F10+G10-1,0) -> 0 | I10: =IF($A10="",0,IF(N(INDEX('In gebruik'!$W:$W,ROW()+(-3)))>0,N(INDEX('In gebruik'!$W:$W,ROW()+(-3))),IF(G10>0,MAX(F10+G10,p_Start),0))) -> 2032 | J10: =IF($A10="","",IF(AND(G10>0,F10+G10<p_Start),"Over levensduur",IF(AND(I10>0,I10<=p_Start+3),"In begrotingsperiode",""))) | K10: =IF($E10="Lease-koop",p_Aanbet,0) -> 0 | L10: =IF($E10="Lease-koop",p_Belet,0) -> 0 | M10: =IF($E10="Lease-koop",p_Opbouw,0) -> 0 | N10: =IF($E10="Lease-koop",p_Slot,0) -> 0 | O10: =IF($E10="Lease-koop",I10+p_SlotJr,0) -> 0 | P10: =IF($E10="Koop",N(INDEX('In gebruik'!$V:$V,ROW()+(-3))),0) -> 0 | Q10: =K10+L10+M10+N10+P10 -> 0 | R10: =IF($E10="Lease-koop",p_AfschrLK,IF($E10="Koop",G10,0)) -> 0 | S10: =IF(R10>0,Q10/R10,0) -> 0 | T10: =IF($E10="Lease-koop",O10+1,IF($E10="Koop",I10+1,0)) -> 0 | U10: =IF($E10="Lease-koop",p_Lease,0) -> 0 | V10: =IF($A10="",0,N(INDEX('In gebruik'!$R:$R,ROW()+(-3)))) -> 0 | W10: =IF($A10="",0,N(INDEX('In gebruik'!$S:$S,ROW()+(-3)))) -> 0 | X10: =IF(W10>0,N(INDEX('In gebruik'!$T:$T,ROW()+(-3))),0) -> 0 | Y10: =IF(W10>0,IF(N(INDEX('In gebruik'!$P:$P,ROW()+(-3)))>0,N(INDEX('In gebruik'!$P:$P,ROW()+(-3))),p_Lease),0) -> 0 | AA10: =IF($Q10+$W10=0,0,IF(AA$7=$I10,$K10+$L10+$M10+$P10,0)+IF(AA$7=$O10,$N10,0)+IF(AA$7=$X10,$W10,0)) -> 0 | AB10: =IF($Q10+$W10=0,0,IF(AB$7=$I10,$K10+$L10+$M10+$P10,0)+IF(AB$7=$O10,$N10,0)+IF(AB$7=$X10,$W10,0)) -> 0 | AC10: =IF($Q10+$W10=0,0,IF(AC$7=$I10,$K10+$L10+$M10+$P10,0)+IF(AC$7=$O10,$N10,0)+IF(AC$7=$X10,$W10,0)) -> 0 | AD10: =IF($Q10+$W10=0,0,IF(AD$7=$I10,$K10+$L10+$M10+$P10,0)+IF(AD$7=$O10,$N10,0)+IF(AD$7=$X10,$W10,0)) -> 0 | AE10: =IF($Q10+$W10=0,0,IF(AE$7=$I10,$K10+$L10+$M10+$P10,0)+IF(AE$7=$O10,$N10,0)+IF(AE$7=$X10,$W10,0)) -> 0 | AF10: =IF($Q10+$W10=0,0,IF(AF$7=$I10,$K10+$L10+$M10+$P10,0)+IF(AF$7=$O10,$N10,0)+IF(AF$7=$X10,$W10,0)) -> 0 | AG10: =IF($Q10+$W10=0,0,IF(AG$7=$I10,$K10+$L10+$M10+$P10,0)+IF(AG$7=$O10,$N10,0)+IF(AG$7=$X10,$W10,0)) -> 0 | AH10: =IF($Q10+$W10=0,0,IF(AH$7=$I10,$K10+$L10+$M10+$P10,0)+IF(AH$7=$O10,$N10,0)+IF(AH$7=$X10,$W10,0)) -> 0 | AJ10: =IF(AND($S10>0,AJ$7>=$T10,AJ$7<$T10+$R10),$S10,0)+IF(AND($W10>0,AJ$7>$X10,AJ$7<=$X10+p_AfschrLK),($V10+$W10)/p_AfschrLK,0) -> 0 | AK10: =IF(AND($S10>0,AK$7>=$T10,AK$7<$T10+$R10),$S10,0)+IF(AND($W10>0,AK$7>$X10,AK$7<=$X10+p_AfschrLK),($V10+$W10)/p_AfschrLK,0) -> 0 | AL10: =IF(AND($S10>0,AL$7>=$T10,AL$7<$T10+$R10),$S10,0)+IF(AND($W10>0,AL$7>$X10,AL$7<=$X10+p_AfschrLK),($V10+$W10)/p_AfschrLK,0) -> 0 | AM10: =IF(AND($S10>0,AM$7>=$T10,AM$7<$T10+$R10),$S10,0)+IF(AND($W10>0,AM$7>$X10,AM$7<=$X10+p_AfschrLK),($V10+$W10)/p_AfschrLK,0) -> 0 | AN10: =IF(AND($S10>0,AN$7>=$T10,AN$7<$T10+$R10),$S10,0)+IF(AND($W10>0,AN$7>$X10,AN$7<=$X10+p_AfschrLK),($V10+$W10)/p_AfschrLK,0) -> 0 | AO10: =IF(AND($S10>0,AO$7>=$T10,AO$7<$T10+$R10),$S10,0)+IF(AND($W10>0,AO$7>$X10,AO$7<=$X10+p_AfschrLK),($V10+$W10)/p_AfschrLK,0) -> 0 | AP10: =IF(AND($S10>0,AP$7>=$T10,AP$7<$T10+$R10),$S10,0)+IF(AND($W10>0,AP$7>$X10,AP$7<=$X10+p_AfschrLK),($V10+$W10)/p_AfschrLK,0) -> 0 | AQ10: =IF(AND($S10>0,AQ$7>=$T10,AQ$7<$T10+$R10),$S10,0)+IF(AND($W10>0,AQ$7>$X10,AQ$7<=$X10+p_AfschrLK),($V10+$W10)/p_AfschrLK,0) -> 0
A11: =IF(INDEX('In gebruik'!$A:$A,ROW()+(-3))="","",INDEX('In gebruik'!$A:$A,ROW()+(-3))) -> V04 | B11: =IF($A11="","",INDEX('In gebruik'!$B:$B,ROW()+(-3))&"") -> V-88-FPL | C11: =IF($A11="","",INDEX('In gebruik'!$H:$H,ROW()+(-3))&"") -> bedrijfsauto | D11: =IF($A11="","",INDEX('In gebruik'!$G:$G,ROW()+(-3))&"") -> Stratenmakers | E11: =IF($A11="","",INDEX('In gebruik'!$U:$U,ROW()+(-3))&"") -> Lease-koop | F11: =IF($A11="",0,N(INDEX('In gebruik'!$J:$J,ROW()+(-3)))) -> 2024 | G11: =IF($A11="",0,N(INDEX('In gebruik'!$K:$K,ROW()+(-3)))) -> 8 | H11: =IF(G11>0,F11+G11-1,0) -> 2031 | I11: =IF($A11="",0,IF(N(INDEX('In gebruik'!$W:$W,ROW()+(-3)))>0,N(INDEX('In gebruik'!$W:$W,ROW()+(-3))),IF(G11>0,MAX(F11+G11,p_Start),0))) -> 2032 | J11: =IF($A11="","",IF(AND(G11>0,F11+G11<p_Start),"Over levensduur",IF(AND(I11>0,I11<=p_Start+3),"In begrotingsperiode",""))) | K11: =IF($E11="Lease-koop",p_Aanbet,0) -> 10000 | L11: =IF($E11="Lease-koop",p_Belet,0) -> 5000 | M11: =IF($E11="Lease-koop",p_Opbouw,0) -> 7000 | N11: =IF($E11="Lease-koop",p_Slot,0) -> 35000 | O11: =IF($E11="Lease-koop",I11+p_SlotJr,0) -> 2034 | P11: =IF($E11="Koop",N(INDEX('In gebruik'!$V:$V,ROW()+(-3))),0) -> 0 | Q11: =K11+L11+M11+N11+P11 -> 57000 | R11: =IF($E11="Lease-koop",p_AfschrLK,IF($E11="Koop",G11,0)) -> 6 | S11: =IF(R11>0,Q11/R11,0) -> 9500 | T11: =IF($E11="Lease-koop",O11+1,IF($E11="Koop",I11+1,0)) -> 2035 | U11: =IF($E11="Lease-koop",p_Lease,0) -> 12000 | V11: =IF($A11="",0,N(INDEX('In gebruik'!$R:$R,ROW()+(-3)))) -> 0 | W11: =IF($A11="",0,N(INDEX('In gebruik'!$S:$S,ROW()+(-3)))) -> 0 | X11: =IF(W11>0,N(INDEX('In gebruik'!$T:$T,ROW()+(-3))),0) -> 0 | Y11: =IF(W11>0,IF(N(INDEX('In gebruik'!$P:$P,ROW()+(-3)))>0,N(INDEX('In gebruik'!$P:$P,ROW()+(-3))),p_Lease),0) -> 0 | AA11: =IF($Q11+$W11=0,0,IF(AA$7=$I11,$K11+$L11+$M11+$P11,0)+IF(AA$7=$O11,$N11,0)+IF(AA$7=$X11,$W11,0)) -> 0 | AB11: =IF($Q11+$W11=0,0,IF(AB$7=$I11,$K11+$L11+$M11+$P11,0)+IF(AB$7=$O11,$N11,0)+IF(AB$7=$X11,$W11,0)) -> 0 | AC11: =IF($Q11+$W11=0,0,IF(AC$7=$I11,$K11+$L11+$M11+$P11,0)+IF(AC$7=$O11,$N11,0)+IF(AC$7=$X11,$W11,0)) -> 0 | AD11: =IF($Q11+$W11=0,0,IF(AD$7=$I11,$K11+$L11+$M11+$P11,0)+IF(AD$7=$O11,$N11,0)+IF(AD$7=$X11,$W11,0)) -> 0 | AE11: =IF($Q11+$W11=0,0,IF(AE$7=$I11,$K11+$L11+$M11+$P11,0)+IF(AE$7=$O11,$N11,0)+IF(AE$7=$X11,$W11,0)) -> 0 | AF11: =IF($Q11+$W11=0,0,IF(AF$7=$I11,$K11+$L11+$M11+$P11,0)+IF(AF$7=$O11,$N11,0)+IF(AF$7=$X11,$W11,0)) -> 22000 | AG11: =IF($Q11+$W11=0,0,IF(AG$7=$I11,$K11+$L11+$M11+$P11,0)+IF(AG$7=$O11,$N11,0)+IF(AG$7=$X11,$W11,0)) -> 0 | AH11: =IF($Q11+$W11=0,0,IF(AH$7=$I11,$K11+$L11+$M11+$P11,0)+IF(AH$7=$O11,$N11,0)+IF(AH$7=$X11,$W11,0)) -> 35000 | AJ11: =IF(AND($S11>0,AJ$7>=$T11,AJ$7<$T11+$R11),$S11,0)+IF(AND($W11>0,AJ$7>$X11,AJ$7<=$X11+p_AfschrLK),($V11+$W11)/p_AfschrLK,0) -> 0 | AK11: =IF(AND($S11>0,AK$7>=$T11,AK$7<$T11+$R11),$S11,0)+IF(AND($W11>0,AK$7>$X11,AK$7<=$X11+p_AfschrLK),($V11+$W11)/p_AfschrLK,0) -> 0 | AL11: =IF(AND($S11>0,AL$7>=$T11,AL$7<$T11+$R11),$S11,0)+IF(AND($W11>0,AL$7>$X11,AL$7<=$X11+p_AfschrLK),($V11+$W11)/p_AfschrLK,0) -> 0 | AM11: =IF(AND($S11>0,AM$7>=$T11,AM$7<$T11+$R11),$S11,0)+IF(AND($W11>0,AM$7>$X11,AM$7<=$X11+p_AfschrLK),($V11+$W11)/p_AfschrLK,0) -> 0 | AN11: =IF(AND($S11>0,AN$7>=$T11,AN$7<$T11+$R11),$S11,0)+IF(AND($W11>0,AN$7>$X11,AN$7<=$X11+p_AfschrLK),($V11+$W11)/p_AfschrLK,0) -> 0 | AO11: =IF(AND($S11>0,AO$7>=$T11,AO$7<$T11+$R11),$S11,0)+IF(AND($W11>0,AO$7>$X11,AO$7<=$X11+p_AfschrLK),($V11+$W11)/p_AfschrLK,0) -> 0 | AP11: =IF(AND($S11>0,AP$7>=$T11,AP$7<$T11+$R11),$S11,0)+IF(AND($W11>0,AP$7>$X11,AP$7<=$X11+p_AfschrLK),($V11+$W11)/p_AfschrLK,0) -> 0 | AQ11: =IF(AND($S11>0,AQ$7>=$T11,AQ$7<$T11+$R11),$S11,0)+IF(AND($W11>0,AQ$7>$X11,AQ$7<=$X11+p_AfschrLK),($V11+$W11)/p_AfschrLK,0) -> 0
A12: =IF(INDEX('In gebruik'!$A:$A,ROW()+(-3))="","",INDEX('In gebruik'!$A:$A,ROW()+(-3))) -> V05 | B12: =IF($A12="","",INDEX('In gebruik'!$B:$B,ROW()+(-3))&"") -> H-872-GK | C12: =IF($A12="","",INDEX('In gebruik'!$H:$H,ROW()+(-3))&"") -> personenauto | D12: =IF($A12="","",INDEX('In gebruik'!$G:$G,ROW()+(-3))&"") -> Kantoor | E12: =IF($A12="","",INDEX('In gebruik'!$U:$U,ROW()+(-3))&"") -> Lease-koop | F12: =IF($A12="",0,N(INDEX('In gebruik'!$J:$J,ROW()+(-3)))) -> 2021 | G12: =IF($A12="",0,N(INDEX('In gebruik'!$K:$K,ROW()+(-3)))) -> 8 | H12: =IF(G12>0,F12+G12-1,0) -> 2028 | I12: =IF($A12="",0,IF(N(INDEX('In gebruik'!$W:$W,ROW()+(-3)))>0,N(INDEX('In gebruik'!$W:$W,ROW()+(-3))),IF(G12>0,MAX(F12+G12,p_Start),0))) -> 2029 | J12: =IF($A12="","",IF(AND(G12>0,F12+G12<p_Start),"Over levensduur",IF(AND(I12>0,I12<=p_Start+3),"In begrotingsperiode",""))) -> In begrotingsperiode | K12: =IF($E12="Lease-koop",p_Aanbet,0) -> 10000 | L12: =IF($E12="Lease-koop",p_Belet,0) -> 5000 | M12: =IF($E12="Lease-koop",p_Opbouw,0) -> 7000 | N12: =IF($E12="Lease-koop",p_Slot,0) -> 35000 | O12: =IF($E12="Lease-koop",I12+p_SlotJr,0) -> 2031 | P12: =IF($E12="Koop",N(INDEX('In gebruik'!$V:$V,ROW()+(-3))),0) -> 0 | Q12: =K12+L12+M12+N12+P12 -> 57000 | R12: =IF($E12="Lease-koop",p_AfschrLK,IF($E12="Koop",G12,0)) -> 6 | S12: =IF(R12>0,Q12/R12,0) -> 9500 | T12: =IF($E12="Lease-koop",O12+1,IF($E12="Koop",I12+1,0)) -> 2032 | U12: =IF($E12="Lease-koop",p_Lease,0) -> 12000 | V12: =IF($A12="",0,N(INDEX('In gebruik'!$R:$R,ROW()+(-3)))) -> 0 | W12: =IF($A12="",0,N(INDEX('In gebruik'!$S:$S,ROW()+(-3)))) -> 0 | X12: =IF(W12>0,N(INDEX('In gebruik'!$T:$T,ROW()+(-3))),0) -> 0 | Y12: =IF(W12>0,IF(N(INDEX('In gebruik'!$P:$P,ROW()+(-3)))>0,N(INDEX('In gebruik'!$P:$P,ROW()+(-3))),p_Lease),0) -> 0 | AA12: =IF($Q12+$W12=0,0,IF(AA$7=$I12,$K12+$L12+$M12+$P12,0)+IF(AA$7=$O12,$N12,0)+IF(AA$7=$X12,$W12,0)) -> 0 | AB12: =IF($Q12+$W12=0,0,IF(AB$7=$I12,$K12+$L12+$M12+$P12,0)+IF(AB$7=$O12,$N12,0)+IF(AB$7=$X12,$W12,0)) -> 0 | AC12: =IF($Q12+$W12=0,0,IF(AC$7=$I12,$K12+$L12+$M12+$P12,0)+IF(AC$7=$O12,$N12,0)+IF(AC$7=$X12,$W12,0)) -> 22000 | AD12: =IF($Q12+$W12=0,0,IF(AD$7=$I12,$K12+$L12+$M12+$P12,0)+IF(AD$7=$O12,$N12,0)+IF(AD$7=$X12,$W12,0)) -> 0 | AE12: =IF($Q12+$W12=0,0,IF(AE$7=$I12,$K12+$L12+$M12+$P12,0)+IF(AE$7=$O12,$N12,0)+IF(AE$7=$X12,$W12,0)) -> 35000 | AF12: =IF($Q12+$W12=0,0,IF(AF$7=$I12,$K12+$L12+$M12+$P12,0)+IF(AF$7=$O12,$N12,0)+IF(AF$7=$X12,$W12,0)) -> 0 | AG12: =IF($Q12+$W12=0,0,IF(AG$7=$I12,$K12+$L12+$M12+$P12,0)+IF(AG$7=$O12,$N12,0)+IF(AG$7=$X12,$W12,0)) -> 0 | AH12: =IF($Q12+$W12=0,0,IF(AH$7=$I12,$K12+$L12+$M12+$P12,0)+IF(AH$7=$O12,$N12,0)+IF(AH$7=$X12,$W12,0)) -> 0 | AJ12: =IF(AND($S12>0,AJ$7>=$T12,AJ$7<$T12+$R12),$S12,0)+IF(AND($W12>0,AJ$7>$X12,AJ$7<=$X12+p_AfschrLK),($V12+$W12)/p_AfschrLK,0) -> 0 | AK12: =IF(AND($S12>0,AK$7>=$T12,AK$7<$T12+$R12),$S12,0)+IF(AND($W12>0,AK$7>$X12,AK$7<=$X12+p_AfschrLK),($V12+$W12)/p_AfschrLK,0) -> 0 | AL12: =IF(AND($S12>0,AL$7>=$T12,AL$7<$T12+$R12),$S12,0)+IF(AND($W12>0,AL$7>$X12,AL$7<=$X12+p_AfschrLK),($V12+$W12)/p_AfschrLK,0) -> 0 | AM12: =IF(AND($S12>0,AM$7>=$T12,AM$7<$T12+$R12),$S12,0)+IF(AND($W12>0,AM$7>$X12,AM$7<=$X12+p_AfschrLK),($V12+$W12)/p_AfschrLK,0) -> 0 | AN12: =IF(AND($S12>0,AN$7>=$T12,AN$7<$T12+$R12),$S12,0)+IF(AND($W12>0,AN$7>$X12,AN$7<=$X12+p_AfschrLK),($V12+$W12)/p_AfschrLK,0) -> 0 | AO12: =IF(AND($S12>0,AO$7>=$T12,AO$7<$T12+$R12),$S12,0)+IF(AND($W12>0,AO$7>$X12,AO$7<=$X12+p_AfschrLK),($V12+$W12)/p_AfschrLK,0) -> 9500 | AP12: =IF(AND($S12>0,AP$7>=$T12,AP$7<$T12+$R12),$S12,0)+IF(AND($W12>0,AP$7>$X12,AP$7<=$X12+p_AfschrLK),($V12+$W12)/p_AfschrLK,0) -> 9500 | AQ12: =IF(AND($S12>0,AQ$7>=$T12,AQ$7<$T12+$R12),$S12,0)+IF(AND($W12>0,AQ$7>$X12,AQ$7<=$X12+p_AfschrLK),($V12+$W12)/p_AfschrLK,0) -> 9500
A13: =IF(INDEX('In gebruik'!$A:$A,ROW()+(-3))="","",INDEX('In gebruik'!$A:$A,ROW()+(-3))) -> V06 | B13: =IF($A13="","",INDEX('In gebruik'!$B:$B,ROW()+(-3))&"") -> V-70-NRS | C13: =IF($A13="","",INDEX('In gebruik'!$H:$H,ROW()+(-3))&"") -> bedrijfsauto | D13: =IF($A13="","",INDEX('In gebruik'!$G:$G,ROW()+(-3))&"") -> Cultuur / Bossen | E13: =IF($A13="","",INDEX('In gebruik'!$U:$U,ROW()+(-3))&"") -> Lease-koop | F13: =IF($A13="",0,N(INDEX('In gebruik'!$J:$J,ROW()+(-3)))) -> 2026 | G13: =IF($A13="",0,N(INDEX('In gebruik'!$K:$K,ROW()+(-3)))) -> 8 | H13: =IF(G13>0,F13+G13-1,0) -> 2033 | I13: =IF($A13="",0,IF(N(INDEX('In gebruik'!$W:$W,ROW()+(-3)))>0,N(INDEX('In gebruik'!$W:$W,ROW()+(-3))),IF(G13>0,MAX(F13+G13,p_Start),0))) -> 2034 | J13: =IF($A13="","",IF(AND(G13>0,F13+G13<p_Start),"Over levensduur",IF(AND(I13>0,I13<=p_Start+3),"In begrotingsperiode",""))) | K13: =IF($E13="Lease-koop",p_Aanbet,0) -> 10000 | L13: =IF($E13="Lease-koop",p_Belet,0) -> 5000 | M13: =IF($E13="Lease-koop",p_Opbouw,0) -> 7000 | N13: =IF($E13="Lease-koop",p_Slot,0) -> 35000 | O13: =IF($E13="Lease-koop",I13+p_SlotJr,0) -> 2036 | P13: =IF($E13="Koop",N(INDEX('In gebruik'!$V:$V,ROW()+(-3))),0) -> 0 | Q13: =K13+L13+M13+N13+P13 -> 57000 | R13: =IF($E13="Lease-koop",p_AfschrLK,IF($E13="Koop",G13,0)) -> 6 | S13: =IF(R13>0,Q13/R13,0) -> 9500 | T13: =IF($E13="Lease-koop",O13+1,IF($E13="Koop",I13+1,0)) -> 2037 | U13: =IF($E13="Lease-koop",p_Lease,0) -> 12000 | V13: =IF($A13="",0,N(INDEX('In gebruik'!$R:$R,ROW()+(-3)))) -> 11000 | W13: =IF($A13="",0,N(INDEX('In gebruik'!$S:$S,ROW()+(-3)))) -> 30000 | X13: =IF(W13>0,N(INDEX('In gebruik'!$T:$T,ROW()+(-3))),0) -> 2028 | Y13: =IF(W13>0,IF(N(INDEX('In gebruik'!$P:$P,ROW()+(-3)))>0,N(INDEX('In gebruik'!$P:$P,ROW()+(-3))),p_Lease),0) -> 11786.52 | AA13: =IF($Q13+$W13=0,0,IF(AA$7=$I13,$K13+$L13+$M13+$P13,0)+IF(AA$7=$O13,$N13,0)+IF(AA$7=$X13,$W13,0)) -> 0 | AB13: =IF($Q13+$W13=0,0,IF(AB$7=$I13,$K13+$L13+$M13+$P13,0)+IF(AB$7=$O13,$N13,0)+IF(AB$7=$X13,$W13,0)) -> 30000 | AC13: =IF($Q13+$W13=0,0,IF(AC$7=$I13,$K13+$L13+$M13+$P13,0)+IF(AC$7=$O13,$N13,0)+IF(AC$7=$X13,$W13,0)) -> 0 | AD13: =IF($Q13+$W13=0,0,IF(AD$7=$I13,$K13+$L13+$M13+$P13,0)+IF(AD$7=$O13,$N13,0)+IF(AD$7=$X13,$W13,0)) -> 0 | AE13: =IF($Q13+$W13=0,0,IF(AE$7=$I13,$K13+$L13+$M13+$P13,0)+IF(AE$7=$O13,$N13,0)+IF(AE$7=$X13,$W13,0)) -> 0 | AF13: =IF($Q13+$W13=0,0,IF(AF$7=$I13,$K13+$L13+$M13+$P13,0)+IF(AF$7=$O13,$N13,0)+IF(AF$7=$X13,$W13,0)) -> 0 | AG13: =IF($Q13+$W13=0,0,IF(AG$7=$I13,$K13+$L13+$M13+$P13,0)+IF(AG$7=$O13,$N13,0)+IF(AG$7=$X13,$W13,0)) -> 0 | AH13: =IF($Q13+$W13=0,0,IF(AH$7=$I13,$K13+$L13+$M13+$P13,0)+IF(AH$7=$O13,$N13,0)+IF(AH$7=$X13,$W13,0)) -> 22000 | AJ13: =IF(AND($S13>0,AJ$7>=$T13,AJ$7<$T13+$R13),$S13,0)+IF(AND($W13>0,AJ$7>$X13,AJ$7<=$X13+p_AfschrLK),($V13+$W13)/p_AfschrLK,0) -> 0 | AK13: =IF(AND($S13>0,AK$7>=$T13,AK$7<$T13+$R13),$S13,0)+IF(AND($W13>0,AK$7>$X13,AK$7<=$X13+p_AfschrLK),($V13+$W13)/p_AfschrLK,0) -> 0 | AL13: =IF(AND($S13>0,AL$7>=$T13,AL$7<$T13+$R13),$S13,0)+IF(AND($W13>0,AL$7>$X13,AL$7<=$X13+p_AfschrLK),($V13+$W13)/p_AfschrLK,0) -> 6833.3333 | AM13: =IF(AND($S13>0,AM$7>=$T13,AM$7<$T13+$R13),$S13,0)+IF(AND($W13>0,AM$7>$X13,AM$7<=$X13+p_AfschrLK),($V13+$W13)/p_AfschrLK,0) -> 6833.3333 | AN13: =IF(AND($S13>0,AN$7>=$T13,AN$7<$T13+$R13),$S13,0)+IF(AND($W13>0,AN$7>$X13,AN$7<=$X13+p_AfschrLK),($V13+$W13)/p_AfschrLK,0) -> 6833.3333 | AO13: =IF(AND($S13>0,AO$7>=$T13,AO$7<$T13+$R13),$S13,0)+IF(AND($W13>0,AO$7>$X13,AO$7<=$X13+p_AfschrLK),($V13+$W13)/p_AfschrLK,0) -> 6833.3333 | AP13: =IF(AND($S13>0,AP$7>=$T13,AP$7<$T13+$R13),$S13,0)+IF(AND($W13>0,AP$7>$X13,AP$7<=$X13+p_AfschrLK),($V13+$W13)/p_AfschrLK,0) -> 6833.3333 | AQ13: =IF(AND($S13>0,AQ$7>=$T13,AQ$7<$T13+$R13),$S13,0)+IF(AND($W13>0,AQ$7>$X13,AQ$7<=$X13+p_AfschrLK),($V13+$W13)/p_AfschrLK,0) -> 6833.3333
A14: =IF(INDEX('In gebruik'!$A:$A,ROW()+(-3))="","",INDEX('In gebruik'!$A:$A,ROW()+(-3))) -> V07 | B14: =IF($A14="","",INDEX('In gebruik'!$B:$B,ROW()+(-3))&"") -> VG-092-L | C14: =IF($A14="","",INDEX('In gebruik'!$H:$H,ROW()+(-3))&"") -> bedrijfsauto | D14: =IF($A14="","",INDEX('In gebruik'!$G:$G,ROW()+(-3))&"") -> Algemene dienst | E14: =IF($A14="","",INDEX('In gebruik'!$U:$U,ROW()+(-3))&"") -> Koop | F14: =IF($A14="",0,N(INDEX('In gebruik'!$J:$J,ROW()+(-3)))) -> 2013 | G14: =IF($A14="",0,N(INDEX('In gebruik'!$K:$K,ROW()+(-3)))) -> 8 | H14: =IF(G14>0,F14+G14-1,0) -> 2020 | I14: =IF($A14="",0,IF(N(INDEX('In gebruik'!$W:$W,ROW()+(-3)))>0,N(INDEX('In gebruik'!$W:$W,ROW()+(-3))),IF(G14>0,MAX(F14+G14,p_Start),0))) -> 2027 | J14: =IF($A14="","",IF(AND(G14>0,F14+G14<p_Start),"Over levensduur",IF(AND(I14>0,I14<=p_Start+3),"In begrotingsperiode",""))) -> Over levensduur | K14: =IF($E14="Lease-koop",p_Aanbet,0) -> 0 | L14: =IF($E14="Lease-koop",p_Belet,0) -> 0 | M14: =IF($E14="Lease-koop",p_Opbouw,0) -> 0 | N14: =IF($E14="Lease-koop",p_Slot,0) -> 0 | O14: =IF($E14="Lease-koop",I14+p_SlotJr,0) -> 0 | P14: =IF($E14="Koop",N(INDEX('In gebruik'!$V:$V,ROW()+(-3))),0) -> 65000 | Q14: =K14+L14+M14+N14+P14 -> 65000 | R14: =IF($E14="Lease-koop",p_AfschrLK,IF($E14="Koop",G14,0)) -> 8 | S14: =IF(R14>0,Q14/R14,0) -> 8125 | T14: =IF($E14="Lease-koop",O14+1,IF($E14="Koop",I14+1,0)) -> 2028 | U14: =IF($E14="Lease-koop",p_Lease,0) -> 0 | V14: =IF($A14="",0,N(INDEX('In gebruik'!$R:$R,ROW()+(-3)))) -> 0 | W14: =IF($A14="",0,N(INDEX('In gebruik'!$S:$S,ROW()+(-3)))) -> 0 | X14: =IF(W14>0,N(INDEX('In gebruik'!$T:$T,ROW()+(-3))),0) -> 0 | Y14: =IF(W14>0,IF(N(INDEX('In gebruik'!$P:$P,ROW()+(-3)))>0,N(INDEX('In gebruik'!$P:$P,ROW()+(-3))),p_Lease),0) -> 0 | AA14: =IF($Q14+$W14=0,0,IF(AA$7=$I14,$K14+$L14+$M14+$P14,0)+IF(AA$7=$O14,$N14,0)+IF(AA$7=$X14,$W14,0)) -> 65000 | AB14: =IF($Q14+$W14=0,0,IF(AB$7=$I14,$K14+$L14+$M14+$P14,0)+IF(AB$7=$O14,$N14,0)+IF(AB$7=$X14,$W14,0)) -> 0 | AC14: =IF($Q14+$W14=0,0,IF(AC$7=$I14,$K14+$L14+$M14+$P14,0)+IF(AC$7=$O14,$N14,0)+IF(AC$7=$X14,$W14,0)) -> 0 | AD14: =IF($Q14+$W14=0,0,IF(AD$7=$I14,$K14+$L14+$M14+$P14,0)+IF(AD$7=$O14,$N14,0)+IF(AD$7=$X14,$W14,0)) -> 0 | AE14: =IF($Q14+$W14=0,0,IF(AE$7=$I14,$K14+$L14+$M14+$P14,0)+IF(AE$7=$O14,$N14,0)+IF(AE$7=$X14,$W14,0)) -> 0 | AF14: =IF($Q14+$W14=0,0,IF(AF$7=$I14,$K14+$L14+$M14+$P14,0)+IF(AF$7=$O14,$N14,0)+IF(AF$7=$X14,$W14,0)) -> 0 | AG14: =IF($Q14+$W14=0,0,IF(AG$7=$I14,$K14+$L14+$M14+$P14,0)+IF(AG$7=$O14,$N14,0)+IF(AG$7=$X14,$W14,0)) -> 0 | AH14: =IF($Q14+$W14=0,0,IF(AH$7=$I14,$K14+$L14+$M14+$P14,0)+IF(AH$7=$O14,$N14,0)+IF(AH$7=$X14,$W14,0)) -> 0 | AJ14: =IF(AND($S14>0,AJ$7>=$T14,AJ$7<$T14+$R14),$S14,0)+IF(AND($W14>0,AJ$7>$X14,AJ$7<=$X14+p_AfschrLK),($V14+$W14)/p_AfschrLK,0) -> 0 | AK14: =IF(AND($S14>0,AK$7>=$T14,AK$7<$T14+$R14),$S14,0)+IF(AND($W14>0,AK$7>$X14,AK$7<=$X14+p_AfschrLK),($V14+$W14)/p_AfschrLK,0) -> 8125 | AL14: =IF(AND($S14>0,AL$7>=$T14,AL$7<$T14+$R14),$S14,0)+IF(AND($W14>0,AL$7>$X14,AL$7<=$X14+p_AfschrLK),($V14+$W14)/p_AfschrLK,0) -> 8125 | AM14: =IF(AND($S14>0,AM$7>=$T14,AM$7<$T14+$R14),$S14,0)+IF(AND($W14>0,AM$7>$X14,AM$7<=$X14+p_AfschrLK),($V14+$W14)/p_AfschrLK,0) -> 8125 | AN14: =IF(AND($S14>0,AN$7>=$T14,AN$7<$T14+$R14),$S14,0)+IF(AND($W14>0,AN$7>$X14,AN$7<=$X14+p_AfschrLK),($V14+$W14)/p_AfschrLK,0) -> 8125 | AO14: =IF(AND($S14>0,AO$7>=$T14,AO$7<$T14+$R14),$S14,0)+IF(AND($W14>0,AO$7>$X14,AO$7<=$X14+p_AfschrLK),($V14+$W14)/p_AfschrLK,0) -> 8125 | AP14: =IF(AND($S14>0,AP$7>=$T14,AP$7<$T14+$R14),$S14,0)+IF(AND($W14>0,AP$7>$X14,AP$7<=$X14+p_AfschrLK),($V14+$W14)/p_AfschrLK,0) -> 8125 | AQ14: =IF(AND($S14>0,AQ$7>=$T14,AQ$7<$T14+$R14),$S14,0)+IF(AND($W14>0,AQ$7>$X14,AQ$7<=$X14+p_AfschrLK),($V14+$W14)/p_AfschrLK,0) -> 8125
A15: =IF(INDEX('In gebruik'!$A:$A,ROW()+(-3))="","",INDEX('In gebruik'!$A:$A,ROW()+(-3))) -> V08 | B15: =IF($A15="","",INDEX('In gebruik'!$B:$B,ROW()+(-3))&"") -> V-72-NRS | C15: =IF($A15="","",INDEX('In gebruik'!$H:$H,ROW()+(-3))&"") -> personenauto | D15: =IF($A15="","",INDEX('In gebruik'!$G:$G,ROW()+(-3))&"") -> Stratenmakers | E15: =IF($A15="","",INDEX('In gebruik'!$U:$U,ROW()+(-3))&"") -> Lease-koop | F15: =IF($A15="",0,N(INDEX('In gebruik'!$J:$J,ROW()+(-3)))) -> 2026 | G15: =IF($A15="",0,N(INDEX('In gebruik'!$K:$K,ROW()+(-3)))) -> 8 | H15: =IF(G15>0,F15+G15-1,0) -> 2033 | I15: =IF($A15="",0,IF(N(INDEX('In gebruik'!$W:$W,ROW()+(-3)))>0,N(INDEX('In gebruik'!$W:$W,ROW()+(-3))),IF(G15>0,MAX(F15+G15,p_Start),0))) -> 2034 | J15: =IF($A15="","",IF(AND(G15>0,F15+G15<p_Start),"Over levensduur",IF(AND(I15>0,I15<=p_Start+3),"In begrotingsperiode",""))) | K15: =IF($E15="Lease-koop",p_Aanbet,0) -> 10000 | L15: =IF($E15="Lease-koop",p_Belet,0) -> 5000 | M15: =IF($E15="Lease-koop",p_Opbouw,0) -> 7000 | N15: =IF($E15="Lease-koop",p_Slot,0) -> 35000 | O15: =IF($E15="Lease-koop",I15+p_SlotJr,0) -> 2036 | P15: =IF($E15="Koop",N(INDEX('In gebruik'!$V:$V,ROW()+(-3))),0) -> 0 | Q15: =K15+L15+M15+N15+P15 -> 57000 | R15: =IF($E15="Lease-koop",p_AfschrLK,IF($E15="Koop",G15,0)) -> 6 | S15: =IF(R15>0,Q15/R15,0) -> 9500 | T15: =IF($E15="Lease-koop",O15+1,IF($E15="Koop",I15+1,0)) -> 2037 | U15: =IF($E15="Lease-koop",p_Lease,0) -> 12000 | V15: =IF($A15="",0,N(INDEX('In gebruik'!$R:$R,ROW()+(-3)))) -> 11000 | W15: =IF($A15="",0,N(INDEX('In gebruik'!$S:$S,ROW()+(-3)))) -> 30000 | X15: =IF(W15>0,N(INDEX('In gebruik'!$T:$T,ROW()+(-3))),0) -> 2028 | Y15: =IF(W15>0,IF(N(INDEX('In gebruik'!$P:$P,ROW()+(-3)))>0,N(INDEX('In gebruik'!$P:$P,ROW()+(-3))),p_Lease),0) -> 11786.52 | AA15: =IF($Q15+$W15=0,0,IF(AA$7=$I15,$K15+$L15+$M15+$P15,0)+IF(AA$7=$O15,$N15,0)+IF(AA$7=$X15,$W15,0)) -> 0 | AB15: =IF($Q15+$W15=0,0,IF(AB$7=$I15,$K15+$L15+$M15+$P15,0)+IF(AB$7=$O15,$N15,0)+IF(AB$7=$X15,$W15,0)) -> 30000 | AC15: =IF($Q15+$W15=0,0,IF(AC$7=$I15,$K15+$L15+$M15+$P15,0)+IF(AC$7=$O15,$N15,0)+IF(AC$7=$X15,$W15,0)) -> 0 | AD15: =IF($Q15+$W15=0,0,IF(AD$7=$I15,$K15+$L15+$M15+$P15,0)+IF(AD$7=$O15,$N15,0)+IF(AD$7=$X15,$W15,0)) -> 0 | AE15: =IF($Q15+$W15=0,0,IF(AE$7=$I15,$K15+$L15+$M15+$P15,0)+IF(AE$7=$O15,$N15,0)+IF(AE$7=$X15,$W15,0)) -> 0 | AF15: =IF($Q15+$W15=0,0,IF(AF$7=$I15,$K15+$L15+$M15+$P15,0)+IF(AF$7=$O15,$N15,0)+IF(AF$7=$X15,$W15,0)) -> 0 | AG15: =IF($Q15+$W15=0,0,IF(AG$7=$I15,$K15+$L15+$M15+$P15,0)+IF(AG$7=$O15,$N15,0)+IF(AG$7=$X15,$W15,0)) -> 0 | AH15: =IF($Q15+$W15=0,0,IF(AH$7=$I15,$K15+$L15+$M15+$P15,0)+IF(AH$7=$O15,$N15,0)+IF(AH$7=$X15,$W15,0)) -> 22000 | AJ15: =IF(AND($S15>0,AJ$7>=$T15,AJ$7<$T15+$R15),$S15,0)+IF(AND($W15>0,AJ$7>$X15,AJ$7<=$X15+p_AfschrLK),($V15+$W15)/p_AfschrLK,0) -> 0 | AK15: =IF(AND($S15>0,AK$7>=$T15,AK$7<$T15+$R15),$S15,0)+IF(AND($W15>0,AK$7>$X15,AK$7<=$X15+p_AfschrLK),($V15+$W15)/p_AfschrLK,0) -> 0 | AL15: =IF(AND($S15>0,AL$7>=$T15,AL$7<$T15+$R15),$S15,0)+IF(AND($W15>0,AL$7>$X15,AL$7<=$X15+p_AfschrLK),($V15+$W15)/p_AfschrLK,0) -> 6833.3333 | AM15: =IF(AND($S15>0,AM$7>=$T15,AM$7<$T15+$R15),$S15,0)+IF(AND($W15>0,AM$7>$X15,AM$7<=$X15+p_AfschrLK),($V15+$W15)/p_AfschrLK,0) -> 6833.3333 | AN15: =IF(AND($S15>0,AN$7>=$T15,AN$7<$T15+$R15),$S15,0)+IF(AND($W15>0,AN$7>$X15,AN$7<=$X15+p_AfschrLK),($V15+$W15)/p_AfschrLK,0) -> 6833.3333 | AO15: =IF(AND($S15>0,AO$7>=$T15,AO$7<$T15+$R15),$S15,0)+IF(AND($W15>0,AO$7>$X15,AO$7<=$X15+p_AfschrLK),($V15+$W15)/p_AfschrLK,0) -> 6833.3333 | AP15: =IF(AND($S15>0,AP$7>=$T15,AP$7<$T15+$R15),$S15,0)+IF(AND($W15>0,AP$7>$X15,AP$7<=$X15+p_AfschrLK),($V15+$W15)/p_AfschrLK,0) -> 6833.3333 | AQ15: =IF(AND($S15>0,AQ$7>=$T15,AQ$7<$T15+$R15),$S15,0)+IF(AND($W15>0,AQ$7>$X15,AQ$7<=$X15+p_AfschrLK),($V15+$W15)/p_AfschrLK,0) -> 6833.3333
A16: =IF(INDEX('In gebruik'!$A:$A,ROW()+(-3))="","",INDEX('In gebruik'!$A:$A,ROW()+(-3))) -> V09 | B16: =IF($A16="","",INDEX('In gebruik'!$B:$B,ROW()+(-3))&"") -> Z-684-FB | C16: =IF($A16="","",INDEX('In gebruik'!$H:$H,ROW()+(-3))&"") -> personenauto | D16: =IF($A16="","",INDEX('In gebruik'!$G:$G,ROW()+(-3))&"") -> Kantoor | E16: =IF($A16="","",INDEX('In gebruik'!$U:$U,ROW()+(-3))&"") -> Lease-koop | F16: =IF($A16="",0,N(INDEX('In gebruik'!$J:$J,ROW()+(-3)))) -> 2024 | G16: =IF($A16="",0,N(INDEX('In gebruik'!$K:$K,ROW()+(-3)))) -> 8 | H16: =IF(G16>0,F16+G16-1,0) -> 2031 | I16: =IF($A16="",0,IF(N(INDEX('In gebruik'!$W:$W,ROW()+(-3)))>0,N(INDEX('In gebruik'!$W:$W,ROW()+(-3))),IF(G16>0,MAX(F16+G16,p_Start),0))) -> 2032 | J16: =IF($A16="","",IF(AND(G16>0,F16+G16<p_Start),"Over levensduur",IF(AND(I16>0,I16<=p_Start+3),"In begrotingsperiode",""))) | K16: =IF($E16="Lease-koop",p_Aanbet,0) -> 10000 | L16: =IF($E16="Lease-koop",p_Belet,0) -> 5000 | M16: =IF($E16="Lease-koop",p_Opbouw,0) -> 7000 | N16: =IF($E16="Lease-koop",p_Slot,0) -> 35000 | O16: =IF($E16="Lease-koop",I16+p_SlotJr,0) -> 2034 | P16: =IF($E16="Koop",N(INDEX('In gebruik'!$V:$V,ROW()+(-3))),0) -> 0 | Q16: =K16+L16+M16+N16+P16 -> 57000 | R16: =IF($E16="Lease-koop",p_AfschrLK,IF($E16="Koop",G16,0)) -> 6 | S16: =IF(R16>0,Q16/R16,0) -> 9500 | T16: =IF($E16="Lease-koop",O16+1,IF($E16="Koop",I16+1,0)) -> 2035 | U16: =IF($E16="Lease-koop",p_Lease,0) -> 12000 | V16: =IF($A16="",0,N(INDEX('In gebruik'!$R:$R,ROW()+(-3)))) -> 0 | W16: =IF($A16="",0,N(INDEX('In gebruik'!$S:$S,ROW()+(-3)))) -> 0 | X16: =IF(W16>0,N(INDEX('In gebruik'!$T:$T,ROW()+(-3))),0) -> 0 | Y16: =IF(W16>0,IF(N(INDEX('In gebruik'!$P:$P,ROW()+(-3)))>0,N(INDEX('In gebruik'!$P:$P,ROW()+(-3))),p_Lease),0) -> 0 | AA16: =IF($Q16+$W16=0,0,IF(AA$7=$I16,$K16+$L16+$M16+$P16,0)+IF(AA$7=$O16,$N16,0)+IF(AA$7=$X16,$W16,0)) -> 0 | AB16: =IF($Q16+$W16=0,0,IF(AB$7=$I16,$K16+$L16+$M16+$P16,0)+IF(AB$7=$O16,$N16,0)+IF(AB$7=$X16,$W16,0)) -> 0 | AC16: =IF($Q16+$W16=0,0,IF(AC$7=$I16,$K16+$L16+$M16+$P16,0)+IF(AC$7=$O16,$N16,0)+IF(AC$7=$X16,$W16,0)) -> 0 | AD16: =IF($Q16+$W16=0,0,IF(AD$7=$I16,$K16+$L16+$M16+$P16,0)+IF(AD$7=$O16,$N16,0)+IF(AD$7=$X16,$W16,0)) -> 0 | AE16: =IF($Q16+$W16=0,0,IF(AE$7=$I16,$K16+$L16+$M16+$P16,0)+IF(AE$7=$O16,$N16,0)+IF(AE$7=$X16,$W16,0)) -> 0 | AF16: =IF($Q16+$W16=0,0,IF(AF$7=$I16,$K16+$L16+$M16+$P16,0)+IF(AF$7=$O16,$N16,0)+IF(AF$7=$X16,$W16,0)) -> 22000 | AG16: =IF($Q16+$W16=0,0,IF(AG$7=$I16,$K16+$L16+$M16+$P16,0)+IF(AG$7=$O16,$N16,0)+IF(AG$7=$X16,$W16,0)) -> 0 | AH16: =IF($Q16+$W16=0,0,IF(AH$7=$I16,$K16+$L16+$M16+$P16,0)+IF(AH$7=$O16,$N16,0)+IF(AH$7=$X16,$W16,0)) -> 35000 | AJ16: =IF(AND($S16>0,AJ$7>=$T16,AJ$7<$T16+$R16),$S16,0)+IF(AND($W16>0,AJ$7>$X16,AJ$7<=$X16+p_AfschrLK),($V16+$W16)/p_AfschrLK,0) -> 0 | AK16: =IF(AND($S16>0,AK$7>=$T16,AK$7<$T16+$R16),$S16,0)+IF(AND($W16>0,AK$7>$X16,AK$7<=$X16+p_AfschrLK),($V16+$W16)/p_AfschrLK,0) -> 0 | AL16: =IF(AND($S16>0,AL$7>=$T16,AL$7<$T16+$R16),$S16,0)+IF(AND($W16>0,AL$7>$X16,AL$7<=$X16+p_AfschrLK),($V16+$W16)/p_AfschrLK,0) -> 0 | AM16: =IF(AND($S16>0,AM$7>=$T16,AM$7<$T16+$R16),$S16,0)+IF(AND($W16>0,AM$7>$X16,AM$7<=$X16+p_AfschrLK),($V16+$W16)/p_AfschrLK,0) -> 0 | AN16: =IF(AND($S16>0,AN$7>=$T16,AN$7<$T16+$R16),$S16,0)+IF(AND($W16>0,AN$7>$X16,AN$7<=$X16+p_AfschrLK),($V16+$W16)/p_AfschrLK,0) -> 0 | AO16: =IF(AND($S16>0,AO$7>=$T16,AO$7<$T16+$R16),$S16,0)+IF(AND($W16>0,AO$7>$X16,AO$7<=$X16+p_AfschrLK),($V16+$W16)/p_AfschrLK,0) -> 0 | AP16: =IF(AND($S16>0,AP$7>=$T16,AP$7<$T16+$R16),$S16,0)+IF(AND($W16>0,AP$7>$X16,AP$7<=$X16+p_AfschrLK),($V16+$W16)/p_AfschrLK,0) -> 0 | AQ16: =IF(AND($S16>0,AQ$7>=$T16,AQ$7<$T16+$R16),$S16,0)+IF(AND($W16>0,AQ$7>$X16,AQ$7<=$X16+p_AfschrLK),($V16+$W16)/p_AfschrLK,0) -> 0
A17: =IF(INDEX('In gebruik'!$A:$A,ROW()+(-3))="","",INDEX('In gebruik'!$A:$A,ROW()+(-3))) -> V10 | B17: =IF($A17="","",INDEX('In gebruik'!$B:$B,ROW()+(-3))&"") -> V-96-LPT | C17: =IF($A17="","",INDEX('In gebruik'!$H:$H,ROW()+(-3))&"") -> bedrijfsauto | D17: =IF($A17="","",INDEX('In gebruik'!$G:$G,ROW()+(-3))&"") -> Storingsdienst | E17: =IF($A17="","",INDEX('In gebruik'!$U:$U,ROW()+(-3))&"") -> Lease-koop | F17: =IF($A17="",0,N(INDEX('In gebruik'!$J:$J,ROW()+(-3)))) -> 2025 | G17: =IF($A17="",0,N(INDEX('In gebruik'!$K:$K,ROW()+(-3)))) -> 8 | H17: =IF(G17>0,F17+G17-1,0) -> 2032 | I17: =IF($A17="",0,IF(N(INDEX('In gebruik'!$W:$W,ROW()+(-3)))>0,N(INDEX('In gebruik'!$W:$W,ROW()+(-3))),IF(G17>0,MAX(F17+G17,p_Start),0))) -> 2033 | J17: =IF($A17="","",IF(AND(G17>0,F17+G17<p_Start),"Over levensduur",IF(AND(I17>0,I17<=p_Start+3),"In begrotingsperiode",""))) | K17: =IF($E17="Lease-koop",p_Aanbet,0) -> 10000 | L17: =IF($E17="Lease-koop",p_Belet,0) -> 5000 | M17: =IF($E17="Lease-koop",p_Opbouw,0) -> 7000 | N17: =IF($E17="Lease-koop",p_Slot,0) -> 35000 | O17: =IF($E17="Lease-koop",I17+p_SlotJr,0) -> 2035 | P17: =IF($E17="Koop",N(INDEX('In gebruik'!$V:$V,ROW()+(-3))),0) -> 0 | Q17: =K17+L17+M17+N17+P17 -> 57000 | R17: =IF($E17="Lease-koop",p_AfschrLK,IF($E17="Koop",G17,0)) -> 6 | S17: =IF(R17>0,Q17/R17,0) -> 9500 | T17: =IF($E17="Lease-koop",O17+1,IF($E17="Koop",I17+1,0)) -> 2036 | U17: =IF($E17="Lease-koop",p_Lease,0) -> 12000 | V17: =IF($A17="",0,N(INDEX('In gebruik'!$R:$R,ROW()+(-3)))) -> 0 | W17: =IF($A17="",0,N(INDEX('In gebruik'!$S:$S,ROW()+(-3)))) -> 0 | X17: =IF(W17>0,N(INDEX('In gebruik'!$T:$T,ROW()+(-3))),0) -> 0 | Y17: =IF(W17>0,IF(N(INDEX('In gebruik'!$P:$P,ROW()+(-3)))>0,N(INDEX('In gebruik'!$P:$P,ROW()+(-3))),p_Lease),0) -> 0 | AA17: =IF($Q17+$W17=0,0,IF(AA$7=$I17,$K17+$L17+$M17+$P17,0)+IF(AA$7=$O17,$N17,0)+IF(AA$7=$X17,$W17,0)) -> 0 | AB17: =IF($Q17+$W17=0,0,IF(AB$7=$I17,$K17+$L17+$M17+$P17,0)+IF(AB$7=$O17,$N17,0)+IF(AB$7=$X17,$W17,0)) -> 0 | AC17: =IF($Q17+$W17=0,0,IF(AC$7=$I17,$K17+$L17+$M17+$P17,0)+IF(AC$7=$O17,$N17,0)+IF(AC$7=$X17,$W17,0)) -> 0 | AD17: =IF($Q17+$W17=0,0,IF(AD$7=$I17,$K17+$L17+$M17+$P17,0)+IF(AD$7=$O17,$N17,0)+IF(AD$7=$X17,$W17,0)) -> 0 | AE17: =IF($Q17+$W17=0,0,IF(AE$7=$I17,$K17+$L17+$M17+$P17,0)+IF(AE$7=$O17,$N17,0)+IF(AE$7=$X17,$W17,0)) -> 0 | AF17: =IF($Q17+$W17=0,0,IF(AF$7=$I17,$K17+$L17+$M17+$P17,0)+IF(AF$7=$O17,$N17,0)+IF(AF$7=$X17,$W17,0)) -> 0 | AG17: =IF($Q17+$W17=0,0,IF(AG$7=$I17,$K17+$L17+$M17+$P17,0)+IF(AG$7=$O17,$N17,0)+IF(AG$7=$X17,$W17,0)) -> 22000 | AH17: =IF($Q17+$W17=0,0,IF(AH$7=$I17,$K17+$L17+$M17+$P17,0)+IF(AH$7=$O17,$N17,0)+IF(AH$7=$X17,$W17,0)) -> 0 | AJ17: =IF(AND($S17>0,AJ$7>=$T17,AJ$7<$T17+$R17),$S17,0)+IF(AND($W17>0,AJ$7>$X17,AJ$7<=$X17+p_AfschrLK),($V17+$W17)/p_AfschrLK,0) -> 0 | AK17: =IF(AND($S17>0,AK$7>=$T17,AK$7<$T17+$R17),$S17,0)+IF(AND($W17>0,AK$7>$X17,AK$7<=$X17+p_AfschrLK),($V17+$W17)/p_AfschrLK,0) -> 0 | AL17: =IF(AND($S17>0,AL$7>=$T17,AL$7<$T17+$R17),$S17,0)+IF(AND($W17>0,AL$7>$X17,AL$7<=$X17+p_AfschrLK),($V17+$W17)/p_AfschrLK,0) -> 0 | AM17: =IF(AND($S17>0,AM$7>=$T17,AM$7<$T17+$R17),$S17,0)+IF(AND($W17>0,AM$7>$X17,AM$7<=$X17+p_AfschrLK),($V17+$W17)/p_AfschrLK,0) -> 0 | AN17: =IF(AND($S17>0,AN$7>=$T17,AN$7<$T17+$R17),$S17,0)+IF(AND($W17>0,AN$7>$X17,AN$7<=$X17+p_AfschrLK),($V17+$W17)/p_AfschrLK,0) -> 0 | AO17: =IF(AND($S17>0,AO$7>=$T17,AO$7<$T17+$R17),$S17,0)+IF(AND($W17>0,AO$7>$X17,AO$7<=$X17+p_AfschrLK),($V17+$W17)/p_AfschrLK,0) -> 0 | AP17: =IF(AND($S17>0,AP$7>=$T17,AP$7<$T17+$R17),$S17,0)+IF(AND($W17>0,AP$7>$X17,AP$7<=$X17+p_AfschrLK),($V17+$W17)/p_AfschrLK,0) -> 0 | AQ17: =IF(AND($S17>0,AQ$7>=$T17,AQ$7<$T17+$R17),$S17,0)+IF(AND($W17>0,AQ$7>$X17,AQ$7<=$X17+p_AfschrLK),($V17+$W17)/p_AfschrLK,0) -> 0
A18: =IF(INDEX('In gebruik'!$A:$A,ROW()+(-3))="","",INDEX('In gebruik'!$A:$A,ROW()+(-3))) -> V11 | B18: =IF($A18="","",INDEX('In gebruik'!$B:$B,ROW()+(-3))&"") | C18: =IF($A18="","",INDEX('In gebruik'!$H:$H,ROW()+(-3))&"") -> bedrijfsauto | D18: =IF($A18="","",INDEX('In gebruik'!$G:$G,ROW()+(-3))&"") -> Cultuur / Bossen | E18: =IF($A18="","",INDEX('In gebruik'!$U:$U,ROW()+(-3))&"") -> Lease-koop | F18: =IF($A18="",0,N(INDEX('In gebruik'!$J:$J,ROW()+(-3)))) -> 2026 | G18: =IF($A18="",0,N(INDEX('In gebruik'!$K:$K,ROW()+(-3)))) -> 8 | H18: =IF(G18>0,F18+G18-1,0) -> 2033 | I18: =IF($A18="",0,IF(N(INDEX('In gebruik'!$W:$W,ROW()+(-3)))>0,N(INDEX('In gebruik'!$W:$W,ROW()+(-3))),IF(G18>0,MAX(F18+G18,p_Start),0))) -> 2034 | J18: =IF($A18="","",IF(AND(G18>0,F18+G18<p_Start),"Over levensduur",IF(AND(I18>0,I18<=p_Start+3),"In begrotingsperiode",""))) | K18: =IF($E18="Lease-koop",p_Aanbet,0) -> 10000 | L18: =IF($E18="Lease-koop",p_Belet,0) -> 5000 | M18: =IF($E18="Lease-koop",p_Opbouw,0) -> 7000 | N18: =IF($E18="Lease-koop",p_Slot,0) -> 35000 | O18: =IF($E18="Lease-koop",I18+p_SlotJr,0) -> 2036 | P18: =IF($E18="Koop",N(INDEX('In gebruik'!$V:$V,ROW()+(-3))),0) -> 0 | Q18: =K18+L18+M18+N18+P18 -> 57000 | R18: =IF($E18="Lease-koop",p_AfschrLK,IF($E18="Koop",G18,0)) -> 6 | S18: =IF(R18>0,Q18/R18,0) -> 9500 | T18: =IF($E18="Lease-koop",O18+1,IF($E18="Koop",I18+1,0)) -> 2037 | U18: =IF($E18="Lease-koop",p_Lease,0) -> 12000 | V18: =IF($A18="",0,N(INDEX('In gebruik'!$R:$R,ROW()+(-3)))) -> 11000 | W18: =IF($A18="",0,N(INDEX('In gebruik'!$S:$S,ROW()+(-3)))) -> 35500 | X18: =IF(W18>0,N(INDEX('In gebruik'!$T:$T,ROW()+(-3))),0) -> 2028 | Y18: =IF(W18>0,IF(N(INDEX('In gebruik'!$P:$P,ROW()+(-3)))>0,N(INDEX('In gebruik'!$P:$P,ROW()+(-3))),p_Lease),0) -> 13448.529 | AA18: =IF($Q18+$W18=0,0,IF(AA$7=$I18,$K18+$L18+$M18+$P18,0)+IF(AA$7=$O18,$N18,0)+IF(AA$7=$X18,$W18,0)) -> 0 | AB18: =IF($Q18+$W18=0,0,IF(AB$7=$I18,$K18+$L18+$M18+$P18,0)+IF(AB$7=$O18,$N18,0)+IF(AB$7=$X18,$W18,0)) -> 35500 | AC18: =IF($Q18+$W18=0,0,IF(AC$7=$I18,$K18+$L18+$M18+$P18,0)+IF(AC$7=$O18,$N18,0)+IF(AC$7=$X18,$W18,0)) -> 0 | AD18: =IF($Q18+$W18=0,0,IF(AD$7=$I18,$K18+$L18+$M18+$P18,0)+IF(AD$7=$O18,$N18,0)+IF(AD$7=$X18,$W18,0)) -> 0 | AE18: =IF($Q18+$W18=0,0,IF(AE$7=$I18,$K18+$L18+$M18+$P18,0)+IF(AE$7=$O18,$N18,0)+IF(AE$7=$X18,$W18,0)) -> 0 | AF18: =IF($Q18+$W18=0,0,IF(AF$7=$I18,$K18+$L18+$M18+$P18,0)+IF(AF$7=$O18,$N18,0)+IF(AF$7=$X18,$W18,0)) -> 0 | AG18: =IF($Q18+$W18=0,0,IF(AG$7=$I18,$K18+$L18+$M18+$P18,0)+IF(AG$7=$O18,$N18,0)+IF(AG$7=$X18,$W18,0)) -> 0 | AH18: =IF($Q18+$W18=0,0,IF(AH$7=$I18,$K18+$L18+$M18+$P18,0)+IF(AH$7=$O18,$N18,0)+IF(AH$7=$X18,$W18,0)) -> 22000 | AJ18: =IF(AND($S18>0,AJ$7>=$T18,AJ$7<$T18+$R18),$S18,0)+IF(AND($W18>0,AJ$7>$X18,AJ$7<=$X18+p_AfschrLK),($V18+$W18)/p_AfschrLK,0) -> 0 | AK18: =IF(AND($S18>0,AK$7>=$T18,AK$7<$T18+$R18),$S18,0)+IF(AND($W18>0,AK$7>$X18,AK$7<=$X18+p_AfschrLK),($V18+$W18)/p_AfschrLK,0) -> 0 | AL18: =IF(AND($S18>0,AL$7>=$T18,AL$7<$T18+$R18),$S18,0)+IF(AND($W18>0,AL$7>$X18,AL$7<=$X18+p_AfschrLK),($V18+$W18)/p_AfschrLK,0) -> 7750 | AM18: =IF(AND($S18>0,AM$7>=$T18,AM$7<$T18+$R18),$S18,0)+IF(AND($W18>0,AM$7>$X18,AM$7<=$X18+p_AfschrLK),($V18+$W18)/p_AfschrLK,0) -> 7750 | AN18: =IF(AND($S18>0,AN$7>=$T18,AN$7<$T18+$R18),$S18,0)+IF(AND($W18>0,AN$7>$X18,AN$7<=$X18+p_AfschrLK),($V18+$W18)/p_AfschrLK,0) -> 7750 | AO18: =IF(AND($S18>0,AO$7>=$T18,AO$7<$T18+$R18),$S18,0)+IF(AND($W18>0,AO$7>$X18,AO$7<=$X18+p_AfschrLK),($V18+$W18)/p_AfschrLK,0) -> 7750 | AP18: =IF(AND($S18>0,AP$7>=$T18,AP$7<$T18+$R18),$S18,0)+IF(AND($W18>0,AP$7>$X18,AP$7<=$X18+p_AfschrLK),($V18+$W18)/p_AfschrLK,0) -> 7750 | AQ18: =IF(AND($S18>0,AQ$7>=$T18,AQ$7<$T18+$R18),$S18,0)+IF(AND($W18>0,AQ$7>$X18,AQ$7<=$X18+p_AfschrLK),($V18+$W18)/p_AfschrLK,0) -> 7750
